Workbook

Sheet Summary
B3: Source wise Units & Power Interruptions
B4: Date | C4: Day | D4: TNEB + WIND+TPP+IEX in kWh | E4: SOLAR POWER (Inline) in kWh | F4: SOLAR POWER (E&D) in kWh | G4: SOLAR POWER (CRNHB) in kWh | H4: SOLAR POWER (Rotary) in kWh | I4: HFO | J4: HSD | K4: TOTAL | L4: EB Power Cut Minutes | M4: No. of power interruptions | N4: Remarks | O4: Solar Total | Q4: No.Of Power cuts
B5: 45748 | C5: tue | D5: =T5 -> 43821.181 | E5: 266.94 | F5: 240.75 | G5: 1368 | H5: 1178.75 | I5: 0 | J5: 0 | K5: =SUM(D5:J5) -> 46875.621 | L5: 0 | M5: 0 | O5: =E5+F5+G5+H5 -> 3054.44 | P5: =E5+F5+G5+H5 -> 3054.44 | Q5: =M5/2 -> 0 | S5: =SUM(E5:J5) -> 3054.44 | T5: ='units overall'!V5-Summary!S5 -> 43821.181
B6: 45749 | C6: wed | D6: =T6 -> 64029.286 | E6: 259.52 | F6: 239.06 | G6: 1125.25 | H6: 1131.75 | I6: 0 | J6: 0 | K6: =SUM(D6:J6) -> 66784.866 | L6: 0 | M6: 0 | O6: =E6+F6+G6+H6 -> 2755.58 | P6: =E6+F6+G6+H6 -> 2755.58 | Q6: =M6/2 -> 0 | S6: =SUM(E6:J6) -> 2755.58 | T6: ='units overall'!V6-Summary!S6 -> 64029.286
B7: 45750 | C7: thu | D7: =T7 -> 66512.297 | E7: 162.75 | F7: 168.78 | G7: 802.5 | H7: 716.5 | I7: 0 | J7: 0 | K7: =SUM(D7:J7) -> 68362.827 | L7: 0 | M7: 0 | O7: =E7+F7+G7+H7 -> 1850.53 | P7: =E7+F7+G7+H7 -> 1850.53 | Q7: =M7/2 -> 0 | S7: =SUM(E7:J7) -> 1850.53 | T7: ='units overall'!V7-Summary!S7 -> 66512.297
B8: 45751 | C8: fri | D8: =T8 -> 67330.756 | E8: 256.77 | F8: 226.13 | G8: 992 | H8: 1085.5 | I8: 0 | J8: 0 | K8: =SUM(D8:J8) -> 69891.156 | L8: 0 | M8: 0 | O8: =E8+F8+G8+H8 -> 2560.4 | P8: =E8+F8+G8+H8 -> 2560.4 | Q8: =M8/2 -> 0 | S8: =SUM(E8:J8) -> 2560.4 | T8: ='units overall'!V8-Summary!S8 -> 67330.756
B9: 45752 | C9: sat | D9: =T9 -> 66795.894 | E9: 241.34 | F9: 229.06 | G9: 986.75 | H9: 1099 | I9: 0 | J9: 0 | K9: =SUM(D9:J9) -> 69352.044 | L9: 0 | M9: 0 | O9: =E9+F9+G9+H9 -> 2556.15 | P9: =E9+F9+G9+H9 -> 2556.15 | Q9: =M9/2 -> 0 | S9: =SUM(E9:J9) -> 2556.15 | T9: ='units overall'!V9-Summary!S9 -> 66795.894
B10: 45753 | C10: sun | D10: =T10 -> 32427.753 | E10: 268.54 | F10: 247.53 | G10: 1099.25 | H10: 1200.75 | I10: 0 | J10: 0 | K10: =SUM(D10:J10) -> 35243.823 | L10: 0 | M10: 0 | O10: =E10+F10+G10+H10 -> 2816.07 | P10: =E10+F10+G10+H10 -> 2816.07 | Q10: =M10/2 -> 0 | S10: =SUM(E10:J10) -> 2816.07 | T10: ='units overall'!V10-Summary!S10 -> 32427.753
B11: 45754 | C11: mon | D11: =T11 -> 66835.108 | E11: 299.01 | F11: 261.34 | G11: 1310 | H11: 1340 | I11: 0 | J11: 0 | K11: =SUM(D11:J11) -> 70045.458 | L11: 0 | M11: 0 | O11: =E11+F11+G11+H11 -> 3210.35 | P11: =E11+F11+G11+H11 -> 3210.35 | Q11: =M11/2 -> 0 | S11: =SUM(E11:J11) -> 3210.35 | T11: ='units overall'!V11-Summary!S11 -> 66835.108
B12: 45755 | C12: tue | D12: =T12 -> 68431.063 | E12: 297.98 | F12: 264.31 | G12: 1508 | H12: 1297.75 | I12: 254 | J12: 556 | K12: =SUM(D12:J12) -> 72609.103 | L12: 10 | M12: 2 | O12: =E12+F12+G12+H12 -> 3368.04 | Q12: =M12/2 -> 1 | S12: =SUM(E12:J12) -> 4178.04 | T12: ='units overall'!V12-Summary!S12 -> 68431.063
B13: 45756 | C13: wed | D13: =T13 -> 69257.705 | E13: 295.55 | F13: 258.91 | G13: 1493.75 | H13: 1626.25 | I13: 0 | J13: 0 | K13: =SUM(D13:J13) -> 72932.165 | L13: 0 | M13: 0 | O13: =E13+F13+G13+H13 -> 3674.46 | P13: =E13+F13+G13+H13 -> 3674.46 | Q13: =M13/2 -> 0 | S13: =SUM(E13:J13) -> 3674.46 | T13: ='units overall'!V13-Summary!S13 -> 69257.705
B14: 45757 | C14: thu | D14: =T14 -> 71372.18 | E14: 299.33 | F14: 253.31 | G14: 1299.75 | H14: 1611.25 | I14: 110.75 | J14: 93.44 | K14: =SUM(D14:J14) -> 75040.01 | L14: 10 | M14: 2 | O14: =E14+F14+G14+H14 -> 3463.64 | P14: =E14+F14+G14+H14 -> 3463.64 | Q14: =M14/2 -> 1 | S14: =SUM(E14:J14) -> 3667.83 | T14: ='units overall'!V14-Summary!S14 -> 71372.18
B15: 45758 | C15: fri | D15: =T15 -> 39987.024 | E15: 288.58 | F15: 248.53 | G15: 1445.75 | H15: 1484.5 | I15: 9766.75 | J15: 18265.13 | K15: =SUM(D15:J15) -> 71486.264 | L15: 760 | M15: 2 | O15: =E15+F15+G15+H15 -> 3467.36 | P15: =E15+F15+G15+H15 -> 3467.36 | Q15: =M15/2 -> 1 | S15: =SUM(E15:J15) -> 31499.24 | T15: ='units overall'!V15-Summary!S15 -> 39987.024
B16: 45759 | C16: sat | D16: =T16 -> 50900.753 | E16: 293.89 | F16: 246.97 | G16: 1471.5 | H16: 835.5 | I16: 4515.25 | J16: 10702.27 | K16: =SUM(D16:J16) -> 68966.133 | L16: 240 | M16: 2 | O16: =E16+F16+G16+H16 -> 2847.86 | Q16: =M16/2 -> 1 | S16: =SUM(E16:J16) -> 18065.38 | T16: ='units overall'!V16-Summary!S16 -> 50900.753
B17: 45760 | C17: sun | D17: =T17 -> 23202.886 | E17: 279.42 | F17: 253.41 | G17: 1451.25 | H17: 1444.75 | I17: 398 | J17: 884.58 | K17: =SUM(D17:J17) -> 27914.296 | L17: 60 | M17: 4 | O17: =E17+F17+G17+H17 -> 3428.83 | Q17: =M17/2 -> 2 | S17: =SUM(E17:J17) -> 4711.41 | T17: ='units overall'!V17-Summary!S17 -> 23202.886
B18: 45761 | C18: mon | D18: =T18 -> 13728.765 | E18: 102.4 | F18: 230.19 | G18: 1034 | H18: 1320 | I18: 0 | J18: 0 | K18: =SUM(D18:J18) -> 16415.355 | L18: 0 | M18: 0 | O18: =E18+F18+G18+H18 -> 2686.59 | Q18: =M18/2 -> 0 | S18: =SUM(E18:J18) -> 2686.59 | T18: ='units overall'!V18-Summary!S18 -> 13728.765
B19: 45762 | C19: tue | D19: =T19 -> 66634.2 | E19: 209.41 | F19: 225.31 | G19: 1210 | H19: 1306.75 | I19: 0 | J19: 0 | K19: =SUM(D19:J19) -> 69585.67 | L19: 0 | M19: 0 | O19: =E19+F19+G19+H19 -> 2951.47 | Q19: =M19/2 -> 0 | S19: =SUM(E19:J19) -> 2951.47 | T19: ='units overall'!V19-Summary!S19 -> 66634.2 | U19: 11.15am to 12.30pm, 5.28pm to 5.35pm, 1.50am to 2.05am, 2.35am to 7.15am(continue next day)
B20: 45763 | C20: wed | D20: =T20 -> 54393.21 | E20: 225.02 | F20: 213.13 | G20: 1139.75 | H20: 1217.75 | I20: 2903 | J20: 8740.72 | K20: =SUM(D20:J20) -> 68832.58 | L20: 220 | M20: 2 | O20: =E20+F20+G20+H20 -> 2795.65 | Q20: =M20/2 -> 1 | S20: =SUM(E20:J20) -> 14439.37 | T20: ='units overall'!V20-Summary!S20 -> 54393.21 | U20: 7.15am(continue from previous day) to 8.47am, 9.46am to 11.23am, 5.06 pm to 5.20 pm, 1.24am to 1.42am, 1.47am to 1.52am, 2.02am to 7.15am(continues to next day)
B21: 45764 | C21: thu | D21: =T21 -> 69428.626 | E21: 287.23 | F21: 250.5 | G21: 1428 | H21: 1555.75 | I21: 0 | J21: 0 | K21: =SUM(D21:J21) -> 72950.106 | L21: 0 | M21: 0 | O21: =E21+F21+G21+H21 -> 3521.48 | Q21: =M21/2 -> 0 | S21: =SUM(E21:J21) -> 3521.48 | T21: ='units overall'!V21-Summary!S21 -> 69428.626 | U21: 7.15am(continue from previous day) to 9.15am, 9.25am to 6.28pm
B22: 45765 | C22: fri | D22: =T22 -> 70483.476 | E22: 255.81 | F22: 232.97 | G22: 1290.75 | H22: 1375.75 | I22: 0 | J22: 0 | K22: =SUM(D22:J22) -> 73638.756 | L22: 0 | M22: 0 | O22: =E22+F22+G22+H22 -> 3155.28 | Q22: =M22/2 -> 0 | S22: =SUM(E22:J22) -> 3155.28 | T22: ='units overall'!V22-Summary!S22 -> 70483.476
B23: 45766 | C23: sat | D23: =T23 -> 69004.078 | E23: 288 | F23: 252.72 | G23: 1442.75 | H23: 1507.75 | I23: 0 | J23: 0 | K23: =SUM(D23:J23) -> 72495.298 | L23: 0 | M23: 0 | O23: =E23+F23+G23+H23 -> 3491.22 | Q23: =M23/2 -> 0 | S23: =SUM(E23:J23) -> 3491.22 | T23: ='units overall'!V23-Summary!S23 -> 69004.078
B24: 45767 | C24: sun | D24: =T24 -> 35875.342 | E24: 291.26 | F24: 256.06 | G24: 1483.75 | H24: 1563.75 | I24: 0 | J24: 0 | K24: =SUM(D24:J24) -> 39470.162 | L24: 0 | M24: 0 | O24: =E24+F24+G24+H24 -> 3594.82 | Q24: =M24/2 -> 0 | S24: =SUM(E24:J24) -> 3594.82 | T24: ='units overall'!V24-Summary!S24 -> 35875.342
B25: 45768 | C25: mon | D25: =T25 -> 72261.341 | E25: 264.9 | F25: 233.47 | G25: 1345.25 | H25: 1436.25 | I25: 0 | J25: 0 | K25: =SUM(D25:J25) -> 75541.211 | L25: 0 | M25: 0 | O25: =E25+F25+G25+H25 -> 3279.87 | Q25: =M25/2 -> 0 | S25: =SUM(E25:J25) -> 3279.87 | T25: ='units overall'!V25-Summary!S25 -> 72261.341
B26: 45769 | C26: tue | D26: =T26 -> 73931.752 | E26: 275.14 | F26: 247.31 | G26: 1403.75 | H26: 1498.25 | I26: 0 | J26: 0 | K26: =SUM(D26:J26) -> 77356.202 | L26: 0 | M26: 0 | O26: =E26+F26+G26+H26 -> 3424.45 | Q26: =M26/2 -> 0 | S26: =SUM(E26:J26) -> 3424.45 | T26: ='units overall'!V26-Summary!S26 -> 73931.752
B27: 45770 | C27: wed | D27: =T27 -> 74138.469 | E27: 306.43 | F27: 264 | G27: 1563.25 | H27: 1654.5 | I27: 0 | J27: 0 | K27: =SUM(D27:J27) -> 77926.649 | L27: 0 | M27: 0 | O27: =E27+F27+G27+H27 -> 3788.18 | Q27: =M27/2 -> 0 | S27: =SUM(E27:J27) -> 3788.18 | T27: ='units overall'!V27-Summary!S27 -> 74138.469
B28: 45771 | C28: thu | D28: =T28 -> 75844.449 | E28: 307.46 | F28: 257.31 | G28: 1557 | H28: 1633 | I28: 0 | J28: 0 | K28: =SUM(D28:J28) -> 79599.219 | L28: 0 | M28: 0 | O28: =E28+F28+G28+H28 -> 3754.77 | Q28: =M28/2 -> 0 | S28: =SUM(E28:J28) -> 3754.77 | T28: ='units overall'!V28-Summary!S28 -> 75844.449
B29: 45772 | C29: fri | D29: =T29 -> 71528.021 | E29: 284.29 | F29: 247.19 | G29: 1433.25 | H29: 1511.75 | I29: 669 | J29: 2317 | K29: =SUM(D29:J29) -> 77990.501 | L29: 35 | M29: 2 | O29: =E29+F29+G29+H29 -> 3476.48 | Q29: =M29/2 -> 1 | S29: =SUM(E29:J29) -> 6462.48 | T29: ='units overall'!V29-Summary!S29 -> 71528.021
B30: 45773 | C30: sat | D30: =T30 -> 69049.52 | E30: 289.15 | F30: 237.22 | G30: 1371.25 | H30: 1493.25 | I30: 0 | J30: 1038.09 | K30: =SUM(D30:J30) -> 73478.48 | L30: 0 | M30: 0 | O30: =E30+F30+G30+H30 -> 3390.87 | Q30: =M30/2 -> 0 | S30: =SUM(E30:J30) -> 4428.96 | T30: ='units overall'!V30-Summary!S30 -> 69049.52 | U30: =53*5 -> 265
B31: 45774 | C31: sun | D31: =T31 -> 18311.621 | E31: 238.02 | F31: 191.56 | G31: 1199.75 | H31: 1224.5 | I31: 6504 | J31: 4070.69 | K31: =SUM(D31:J31) -> 31740.141 | L31: 530 | M31: 2 | O31: =E31+F31+G31+H31 -> 2853.83 | Q31: =M31/2 -> 1 | S31: =SUM(E31:J31) -> 13428.52 | T31: ='units overall'!V31-Summary!S31 -> 18311.621
B32: 45775 | C32: mon | D32: =T32 -> 71441.734 | E32: 263.17 | F32: 241.94 | G32: 1373.5 | H32: 1372.25 | I32: 0 | J32: 0 | K32: =SUM(D32:J32) -> 74692.594 | L32: 0 | M32: 0 | O32: =E32+F32+G32+H32 -> 3250.86 | Q32: =M32/2 -> 0 | S32: =SUM(E32:J32) -> 3250.86 | T32: ='units overall'!V32-Summary!S32 -> 71441.734
B33: 45776 | C33: tue | D33: =T33 -> 73596.77 | E33: 284.35 | F33: 238.63 | G33: 1474.25 | H33: 1504 | I33: 0 | J33: 0 | K33: =SUM(D33:J33) -> 77098 | L33: 0 | M33: 0 | O33: =E33+F33+G33+H33 -> 3501.23 | Q33: =M33/2 -> 0 | S33: =SUM(E33:J33) -> 3501.23 | T33: ='units overall'!V33-Summary!S33 -> 73596.77
B34: 45777 | C34: wed | D34: =T34 -> 68689.359 | E34: 297.54 | F34: 253.75 | G34: 1502 | H34: 1539.75 | I34: 45 | J34: 13 | K34: =SUM(D34:J34) -> 72340.399 | L34: 10 | M34: 2 | O34: =E34+F34+G34+H34 -> 3593.04 | P34: =F34+G34+H34+I34 -> 3340.5 | Q34: =M34/2 -> 1 | S34: =SUM(E34:J34) -> 3651.04 | T34: ='units overall'!V34-Summary!S34 -> 68689.359
D35: =T35 -> 0 | K35: =SUM(D35:J35) -> 0 | O35: =E35+F35+G35+H35 -> 0 | P35: =F35+G35+H35+I35 -> 0 | Q35: =M35/2 -> 0 | S35: =SUM(E35:J35) -> 0 | T35: ='units overall'!V35-Summary!S35 -> 0
B36: Total | D36: =SUM(D5:D35) -> 1779244.6 | E36: =SUM(E5:E35) -> 7979.2 | F36: =SUM(F5:F35) -> 7211.35 | G36: =SUM(G5:G35) -> 39606 | H36: =SUM(H5:H35) -> 40767.25 | I36: =SUM(I5:I35) -> 25165.75 | J36: =SUM(J5:J35) -> 46680.92 | K36: =SUM(K5:K35) -> 1946655.1 | ... M36: =SUM(M5:M35) -> 20 | O36: =SUM(O5:O35) -> 95563.8 | P36: =SUM(P5:P35) -> 32749.48 | Q36: =SUM(Q5:Q35) -> 10
E38: Sunday | J38: =I36+J36 -> 71846.67 | K38: =787318-784635 -> 2683
J39: =J38*0.1 -> 7184.667
D47: =242369/K36 -> 0.12450536 | K47: =393951/K36 -> 0.20237329
D48: =393951/K36 -> 0.20237329

Sheet units overall
B3: Split up Units
B4: Date | C4: Day | D4: Heat Trt | E4: AC (Production) | F4: MGC Cell AC units | G4: AC (UPS room, PC server, Finance) | H4: Canteen + HR + Mrktng + Security + STP | I4: Nozzle soft (Heat trt area) | J4: Main building Compressor | K4: CAT Compressor | L4: Main Building | M4: Lighting | N4: HFO Aux. | O4: Other Areas | P4: Rotary | Q4: E&D | R4: CR NHB | S4: Inline | T4: HT insourcing for CRNHB+Air | U4: CTA | V4: Total (Rotary+E&D+ CR NHB) | W4: Remarks
B5: 45748 | C5: tue | D5: 1465.1392 | E5: 2796.4032 | F5: 401.5 | G5: 599.97 | H5: 962.26 | I5: 299.1 | J5: 627.2928 | K5: 818.9656 | L5: 3262.19 | M5: 747.75 | N5: 223.1 | O5: 1677.701 | P5: =SUM(D5:O5) -> 13881.372 | Q5: 13788.28 | R5: 16629.13 | S5: 546.6716 | T5: 642.0192 | U5: 1388.1486 | V5: =SUM(P5:S5)+T5+U5 -> 46875.621 | X5: =Summary!K5 -> 46875.621 | Z5: 0
B6: 45749 | C6: wed | D6: 3672.8832 | E6: 4693.5552 | F6: 677.38 | G6: 689.89 | H6: 897.75 | I6: 569.68 | J6: 1318.2624 | K6: 1721.0648 | L6: 7257.73 | M6: 794.62 | N6: 188.29 | O6: 2158.296 | P6: =SUM(D6:O6) -> 24639.402 | Q6: 14681.3 | R6: 22550 | S6: 1154.5436 | T6: 1581.1936 | U6: 2178.4276 | V6: =SUM(P6:S6)+T6+U6 -> 66784.866 | X6: =Summary!K6 -> 66784.866 | Z6: =X6-V6 -> 0
B7: 45750 | C7: thu | D7: 3475.7408 | E7: 4549.2576 | F7: 646.5 | G7: 633.31 | H7: 929.98 | I7: 696.35 | J7: 1440.414 | K7: 1880.5405 | L7: 8742.03 | M7: 844.38 | N7: 555.26 | O7: 2482.9223 | P7: =SUM(D7:O7) -> 26876.685 | Q7: 13920.79 | R7: 22362.311 | S7: 1206.0229 | T7: 1517.7572 | U7: 2479.2614 | V7: =SUM(P7:S7)+T7+U7 -> 68362.827 | X7: =Summary!K7 -> 68362.827 | Z7: =X7-V7 -> 0
B8: 45751 | C8: fri | D8: 3728.816 | E8: 5121.1776 | F8: 663 | G8: 679.7 | H8: 882.31 | I8: 644.17 | J8: 1522.8576 | K8: 1988.1752 | L8: 9788.27 | M8: 849.37 | N8: 467.97 | O8: 2011.951 | P8: =SUM(D8:O8) -> 28347.767 | Q8: 13508.12 | R8: 22562.355 | S8: 1331.3007 | T8: 1625.7752 | U8: 2515.8374 | V8: =SUM(P8:S8)+T8+U8 -> 69891.156 | X8: =Summary!K8 -> 69891.156 | Z8: =X8-V8 -> 0
B9: 45752 | C9: sat | D9: 3400.2272 | E9: 4800.3168 | F9: 612.87 | G9: 686.62 | H9: 910.98 | I9: 658.68 | J9: 1545.1956 | K9: 2017.3387 | L9: 9626.41 | M9: 843 | N9: 495.23 | O9: 2284.1089 | P9: =SUM(D9:O9) -> 27880.977 | Q9: 13564.3 | R9: 22770.429 | S9: 1257.5277 | T9: 1499.9021 | U9: 2378.9074 | V9: =SUM(P9:S9)+T9+U9 -> 69352.044 | X9: =Summary!K9 -> 69352.044 | Z9: =X9-V9 -> 0
B10: 45753 | C10: sun | D10: 1274.9952 | E10: 511.3824 | F10: 98.13 | G10: 579.2 | H10: 729.57 | I10: 16.59 | J10: 273.3336 | K10: 356.8522 | L10: 2421.45 | M10: 346.25 | N10: 467.2 | O10: 2329.5834 | P10: =SUM(D10:O10) -> 9404.5368 | Q10: 7289 | R10: 17455.3 | S10: 336.5004 | T10: 528.4154 | U10: 230.0708 | V10: =SUM(P10:S10)+T10+U10 -> 35243.823 | X10: =Summary!K10 -> 35243.823 | Z10: =X10-V10 -> 0
B11: 45754 | C11: mon | D11: 2277.3056 | E11: 5116.8192 | F11: 598.12 | G11: 707.45 | H11: 978.84 | I11: 682.58 | J11: 1549.3284 | K11: 2022.7343 | L11: 10113.35 | M11: 917 | N11: 493.44 | O11: 2649.6875 | P11: =SUM(D11:O11) -> 28106.655 | Q11: 13881.44 | R11: 23109.18 | S11: 1123.3572 | T11: 1061.7201 | U11: 2763.1052 | V11: =SUM(P11:S11)+T11+U11 -> 70045.458 | X11: =Summary!K11 -> 70045.458 | Z11: =X11-V11 -> 0
B12: 45755 | C12: tue | D12: 3877.9584 | E12: 5347.536 | F12: 617.63 | G12: 699.58 | H12: 910.13 | I12: 663.38 | J12: 1493.8956 | K12: 1950.3637 | L12: 9708.71 | M12: 897.38 | N12: 456.06 | O12: 2278.1927 | P12: =SUM(D12:O12) -> 28900.816 | Q12: 15002.3 | R12: 23022.231 | S12: 1395.9436 | T12: 1680.8159 | U12: 2606.9958 | V12: =SUM(P12:S12)+T12+U12 -> 72609.103 | X12: =Summary!K12 -> 72609.103 | Z12: =X12-V12 -> 0
B13: 45756 | C13: wed | D13: 3934.6048 | E13: 5315.7696 | F13: 616.75 | G13: 714.5 | H13: 922.56 | I13: 653.42 | J13: 1551.1896 | K13: 2025.1642 | L13: 10062.97 | M13: 868 | N13: 489.47 | O13: 2292.5248 | P13: =SUM(D13:O13) -> 29446.923 | Q13: 15043.17 | R13: 22847.933 | S13: 1422.0236 | T13: 1709.3094 | U13: 2462.8054 | V13: =SUM(P13:S13)+T13+U13 -> 72932.165 | X13: =Summary!K13 -> 72932.165 | Z13: =X13-V13 -> 0
B14: 45757 | C14: thu | D14: 3565.0496 | E14: 5295.8784 | F14: 631.75 | G14: 725.07 | H14: 978.43 | I14: 722.13 | J14: 1596.9888 | K14: 2084.9576 | L14: 10263.47 | M14: 884.37 | N14: 506.88 | O14: 2616.5403 | P14: =SUM(D14:O14) -> 29871.515 | Q14: 15950.02 | R14: 23516.354 | S14: 1375.2185 | T14: 1570.0407 | U14: 2756.8623 | V14: =SUM(P14:S14)+T14+U14 -> 75040.01 | X14: =Summary!K14 -> 75040.01 | Z14: =X14-V14 -> 0
B15: 45758 | C15: fri | D15: 3543.4048 | E15: 5442.7104 | F15: 571.87 | G15: 742.8 | H15: 929.48 | I15: 680.21 | J15: 1610.9028 | K15: 2103.1231 | L15: 10024.1 | M15: 872.63 | N15: 587.01 | O15: 2331.5341 | P15: =SUM(D15:O15) -> 29439.775 | Q15: 13905.69 | R15: 22499.047 | S15: 1354.8188 | T15: 1563.1317 | U15: 2723.8014 | V15: =SUM(P15:S15)+T15+U15 -> 71486.264 | X15: =Summary!K15 -> 71486.264 | Z15: =X15-V15 -> 0
B16: 45759 | C16: sat | D16: 3680.6592 | E16: 4938.576 | F16: 572.25 | G16: 619.54 | H16: 888.3 | I16: 626.85 | J16: 1353.42 | K16: 1766.965 | L16: 8808.28 | M16: 858.87 | N16: 467.58 | O16: 2391.8529 | P16: =SUM(D16:O16) -> 26973.143 | Q16: 13968.71 | R16: 22560.857 | S16: 1283.6323 | T16: 1588.1375 | U16: 2591.6527 | V16: =SUM(P16:S16)+T16+U16 -> 68966.133 | X16: =Summary!K16 -> 68966.133 | Z16: =X16-V16 -> 0
B17: 45760 | C17: sun | D17: 2748.3168 | E17: 303.8016 | F17: 82.25 | G17: 548.54 | H17: 664.36 | I17: 50.43 | J17: 241.6824 | K17: 315.5298 | L17: 1759.84 | M17: 348.25 | N17: 239.23 | O17: 1841.0106 | P17: =SUM(D17:O17) -> 9143.2412 | Q17: 6278.08 | R17: 10621.01 | S17: 549.70235 | T17: 1100.4149 | U17: 221.8472 | V17: =SUM(P17:S17)+T17+U17 -> 27914.296 | X17: =Summary!K17 -> 27914.296 | Z17: =X17-V17 -> 0
... B34: 45777 | C34: wed | D34: 2677.1552 | E34: 5949.7824 | F34: 193.12 | G34: 751.61 | H34: 904.65 | I34: 731.98 | J34: 1509.8976 | K34: 1971.2552 | L34: 8916.68 | M34: 903.12 | N34: 193.54 | O34: 2810.4842 | P34: =SUM(D34:O34) -> 27513.275 | Q34: 15499.2 | R34: 23831.526 | S34: 1175.9317 | T34: 1213.5301 | U34: 3106.9366 | V34: =SUM(P34:S34)+T34+U34 -> 72340.399 | X34: =Summary!K34 -> 72340.399 | Z34: =X34-V34 -> 0
P35: =SUM(D35:O35) -> 0 | V35: =SUM(P35:S35)+T35+U35 -> 0 | X35: =Summary!K35 -> 0 | Z35: =X35-V35 -> 0
B36: Total | D36: =SUM(D5:D35) -> 90072.611 | E36: =SUM(E5:E35) -> 135952.16 | F36: =SUM(F5:F35) -> 15139.25 | G36: =SUM(G5:G35) -> 21062.51 | H36: =SUM(H5:H35) -> 27814.15 | I36: =SUM(I5:I35) -> 17807.71 | J36: =SUM(J5:J35) -> 38879.194 | K36: =SUM(K5:K35) -> 50758.947 | ... V36: =SUM(V5:V35) -> 1946655.1 | X36: =762370-V36 -> -1184285.1
E37: =E36+F36+G36 -> 172153.92 | J37: =J36+K36 -> 89638.141 | K37: 5720
I38: =(I35/P42)*100 -> 0 | N38: =(N35/P42)*100 -> 0 | V38: =V36/100000 -> 19.466551
D39: =(D36/P42)*100 -> 11.351523 | E39: =(E36/P42)*100 -> 17.133555 | F39: =(F36/P42)*100 -> 1.9079445 | G39: =(G36/P42)*100 -> 2.6544314 | H39: =(H36/P42)*100 -> 3.5053159 | J39: =(J36/P42)*100 -> 4.899803 | K39: =(K36/P42)*100 -> 6.3969651 | L39: =(L36/P42)*100 -> 30.911732 | M39: =(M36/P42)*100 -> 3.0092094 | O39: =(O36/P42)*100 -> 9.3606068 | P39: =(P36/P42)*100 -> 94.78272 | Q39: =((Q36*0.1)/P42)*100 -> 5.2172797 | X39: =1677898-V36 -> -268757.09
P40: =425147-45898-102476-22434-12605-2005 -> 239729 | Q40: 20801.26
P41: =45898+239729+102476+22434+12605+2005 -> 425147 | Q41: 1185.23
P42: =P36+(Q36*0.1) -> 793484.83 | V42: =1007222-V36 -> -939433.09
D43: =D39 -> 11.351523 | E43: =E39+F39 -> 19.041499 | H43: =H39 -> 3.5053159 | J43: =J39+K39 -> 11.296768 | L43: =L39+I38 -> 30.911732 | M43: =M39 -> 3.0092094 | O43: =O39+N38+G39+Q39 -> 17.232318 | P43: =D43+E43+H43+J43+L43+M43+O43 -> 96.348365
K45: =33106-32560 -> 546
Q47: =P36+(Q36*0.015) -> 758296.25 | R47: =Q48-5.79 -> 1.7929625 | S47: =S36/100000 -> 0.33903201
M48: Units in Lacs Jan-24 upto 18th | Q48: =Q47/100000 -> 7.5829625
M49: Total | N49: =SUM(N50:N54) -> 18.783675
M50: MFI | N50: =(P36+(Q36*0.015))/100000 -> 7.5829625
M51: CRNHB | N51: =R36/100000 -> 6.3889006
M52: E&D | N52: =(Q36*0.985)/100000 -> 4.0777348
M53: Inline | N53: =S36/100000 -> 0.33903201
M54: HT insource for CRNHB | N54: =T36/100000 -> 0.39504524

Sheet HT Split up
AK1: HT insourcing for CRNHB
E2: SQF-3 Preheating | H2: VHF-I & II (Heater& Quench Motor, SPM cell workshop) | I2: VHF-1,2,3(convection pump,vacuum pump, water pump & Control supply)+, SQF 2 control supply | J2: SQF-2, Descaling Furnace, GNF-1 and Preheating (SQF-1&2),SQF-1&2 PDB (SQF1&2 Hot to cold Sump motor's.) | K2: SPM Cell(Assembly section), TEM Washing – I, Tempering Furnace, | L2: Low Tempering, HTC LAB, Cooling Tower, Post Wash,Water cooling pump, Coolant Treatment Plant | M2: Near FBF PDB (GNF crane,) GNF - 2,Tempost wash - 2, ENDO staircase Near PDB (Parco oven,20bar washing, Gala - 02nos , HTC cell Roof Fans)
B3: Meter name | D3: STP | E3: SQF cell | F3: SQF-3 Furnace | G3: N2 Plant | H3: VHF- II | I3: VHF-II control supply (550kVA UPS supply) | J3: HT-1 | K3: HT-2 | L3: HT-3 | M3: HT-4 | N3: SQF-3 Post Wash | O3: GNF-3 | P3: GNF-4 | Q3: GNF-5 | R3: GNF-6 | S3: GNF-7 | T3: Parco | U3: Endo-2 | V3: Elva (550kVA UPS supply) | W3: TEM POST | X3: Endo-3 | Y3: Endo-1 | Z3: Insight washing | AA3: High Tempering furnace | AB3: VHF III | AC3: Motor Load | AD3: SQF-1
B4: Loads Connected | C4: Day | D4: Surface Treatment Plant (STP) | E4: SQF-3 Preheating, New Sub zero, Atlas Compressor * (stand by), Multi stage Evaporator,Summit Air Drier(stand by) | F4: SQF-3 Furnace | G4: Nitrogen plant | H4: VHF-I & II (Heater& Quench Motor, SPM cell workshop) | I4: VHF-1,2,3(convection pump,vacuum pump, water pump & Control supply)+, SQF control supply | J4: SQF-2, Descaling Furnace, GNF-1 and Preheating (SQF-1&2) | K4: FBF-1, SPM Cell(Assembly section), TEM Washing – I, Tempering Furnace,PDB | L4: Low Tempering, ETP, Sub Zero(old), LAB, Cooling Tower, Post Wash, Coolant Treatment Plant | M4: FBF-2,3, Gala PDB, GNF-2 VCO Tempering, ENDO Gas PDB, Pre-washing, 7 UVD machine | N4: SQF-3 Post Wash | O4: GNF-3 | P4: GNF-4 | Q4: GNF-5 | R4: GNF-6 | S4: GNF-7(Activation Furnace) | T4: Parco | U4: Endo-2 | V4: Elva Induction hardening | W4: TEM POST WASH | X4: Endo-3 | Y4: Endo-1 | Z4: Insight washing | AA4: High Tempering furnace | AB4: VHF III (Heater & Quench Motor) | AC4: Motor Load (TEM-1 & SQF-1,2 Alternate supply) | AD4: SQF-1 | AE4: Total Heat Treatment | AG4: Date | AH4: Day | AI4: Total | AK4: HT insourcing for CRNHB & inline
B5: 45748 | C5: tue | D5: 0 | E5: 141.89 | F5: 263.17 | G5: 544.34 | H5: 34.34 | I5: 68.48 | J5: 0 | K5: 124.44 | L5: 362.79 | M5: 450.35 | N5: 0.83 | O5: 0 | P5: 0 | Q5: 2.31 | R5: 2.68 | S5: 0 | T5: 0 | U5: 151.92 | V5: 0 | W5: 12.3 | X5: 129.44 | Y5: 0 | Z5: 0 | AA5: 0 | AB5: 0 | AC5: 0 | AD5: 0 | AE5: =SUM(D5:AD5) -> 2289.28 | AG5: 45748 | AH5: tue | AI5: =AE5-AK5 -> 1465.1392 | AK5: 824.1408
B6: 45749 | C6: wed | D6: 138.54 | E6: 608.64 | F6: 1278.97 | G6: 632.86 | H6: 32.01 | I6: 255.04 | J6: 0 | K6: 237.21 | L6: 359.62 | M6: 407.94 | N6: 889.09 | O6: 0 | P6: 0 | Q6: 2.3 | R6: 2.57 | S6: 0 | T6: 0 | U6: 365.52 | V6: 0 | W6: 50.5 | X6: 128.57 | Y6: 0 | Z6: 0 | AA6: 0 | AB6: 349.5 | AC6: 0 | AD6: 0 | AE6: =SUM(D6:AD6) -> 5738.88 | AG6: 45749 | AH6: wed | AI6: =AE6-AK6 -> 3672.8832 | AK6: 2065.9968
B7: 45750 | C7: thu | D7: 513.37 | E7: 748.1 | F7: 850.95 | G7: 422.7 | H7: 34.34 | I7: 282.3 | J7: 0 | K7: 202 | L7: 346.41 | M7: 457.9 | N7: 822.4 | O7: 0 | P7: 0 | Q7: 203.46 | R7: 2.56 | S7: 0 | T7: 6.3 | U7: 350.115 | V7: 0 | W7: 42.96 | X7: 128.7 | Y7: 0 | Z7: 0 | AA7: 0 | AB7: 16.28 | AC7: 0 | AD7: 0 | AE7: =SUM(D7:AD7) -> 5430.845 | AG7: 45750 | AH7: thu | AI7: =AE7-AK7 -> 3475.7408 | AK7: 1955.1042
B8: 45751 | C8: fri | D8: 158.59 | E8: 697.84 | F8: 1167.87 | G8: 529.59 | H8: 18.35 | I8: 244.93 | J8: 0 | K8: 221.15 | L8: 280.82 | M8: 443.28 | N8: 970.18 | O8: 0 | P8: 0 | Q8: 263.34 | R8: 196.41 | S8: 0 | T8: 105.94 | U8: 351.645 | V8: 0 | W8: 47.92 | X8: 128.42 | Y8: 0 | Z8: 0 | AA8: 0 | AB8: 0 | AC8: 0 | AD8: 0 | AE8: =SUM(D8:AD8) -> 5826.275 | AG8: 45751 | AH8: fri | AI8: =AE8-AK8 -> 3728.816 | AK8: 2097.459
B9: 45752 | C9: sat | D9: 494.4 | E9: 668.21 | F9: 784.9 | G9: 488.64 | H9: 33 | I9: 277.89 | J9: 0 | K9: 177.04 | L9: 385.11 | M9: 396.16 | N9: 828.48 | O9: 0 | P9: 0 | Q9: 67.7 | R9: 239.92 | S9: 0 | T9: 7.93 | U9: 303.885 | V9: 0 | W9: 31.23 | X9: 128.36 | Y9: 0 | Z9: 0 | AA9: 0 | AB9: 0 | AC9: 0 | AD9: 0 | AE9: =SUM(D9:AD9) -> 5312.855 | AG9: 45752 | AH9: sat | AI9: =AE9-AK9 -> 3400.2272 | AK9: 1912.6278
B10: 45753 | C10: sun | D10: 0.93 | E10: 63 | F10: 192 | G10: 391.38 | H10: 26.36 | I10: 242.37 | J10: 0 | K10: 60.31 | L10: 259.02 | M10: 272.27 | N10: 67.77 | O10: 0 | P10: 0 | Q10: 8.09 | R10: 56.82 | S10: 0 | T10: 0 | U10: 208.71 | V10: 0 | W10: 14.58 | X10: 128.57 | Y10: 0 | Z10: 0 | AA10: 0 | AB10: 0 | AC10: 0 | AD10: 0 | AE10: =SUM(D10:AD10) -> 1992.18 | AG10: 45753 | AH10: sun | AI10: =AE10-AK10 -> 1274.9952 | AK10: 717.1848
B11: 45754 | C11: mon | D11: 16.63 | E11: 213.92 | F11: 465.92 | G11: 453.05 | H11: 13.11 | I11: 266.17 | J11: 0 | K11: 210.84 | L11: 260.33 | M11: 249.62 | N11: 242.5 | O11: 0 | P11: 0 | Q11: 176.08 | R11: 208.02 | S11: 0 | T11: 0 | U11: 217.2 | V11: 0 | W11: 42.48 | X11: 128.17 | Y11: 0 | Z11: 0 | AA11: 0 | AB11: 394.25 | AC11: 0 | AD11: 0 | AE11: =SUM(D11:AD11) -> 3558.29 | AG11: 45754 | AH11: mon | AI11: =AE11-AK11 -> 2277.3056 | AK11: 1280.9844
B12: 45755 | C12: tue | D12: 154.27 | E12: 794.63 | F12: 1148.16 | G12: 333.82 | H12: 32.09 | I12: 327.94 | J12: 0 | K12: 247.64 | L12: 324.63 | M12: 331.64 | N12: 987.26 | O12: 0 | P12: 0 | Q12: 264.74 | R12: 252.43 | S12: 0 | T12: 84.16 | U12: 346.8 | V12: 4 | W12: 54.72 | X12: 130.18 | Y12: 0 | Z12: 0 | AA12: 0 | AB12: 240.2 | AC12: 0 | AD12: 0 | AE12: =SUM(D12:AD12) -> 6059.31 | AG12: 45755 | AH12: tue | AI12: =AE12-AK12 -> 3877.9584 | AK12: 2181.3516
B13: 45756 | C13: wed | D13: 481.24 | E13: 855.41 | F13: 1078.52 | G13: 398.5 | H13: 32.36 | I13: 330.43 | J13: 0 | K13: 229.04 | L13: 366.49 | M13: 454.84 | N13: 949.06 | O13: 0 | P13: 0 | Q13: 96.7 | R13: 55.77 | S13: 0 | T13: 5.76 | U13: 356.49 | V13: 8 | W13: 39.63 | X13: 130.12 | Y13: 0 | Z13: 0 | AA13: 0 | AB13: 279.46 | AC13: 0 | AD13: 0 | AE13: =SUM(D13:AD13) -> 6147.82 | AG13: 45756 | AH13: wed | AI13: =AE13-AK13 -> 3934.6048 | AK13: 2213.2152
B14: 45757 | C14: thu | D14: 129.66 | E14: 701.53 | F14: 968.96 | G14: 490.54 | H14: 31.64 | I14: 292.16 | J14: 0 | K14: 242.97 | L14: 350.04 | M14: 292.64 | N14: 922.88 | O14: 0 | P14: 0 | Q14: 6.25 | R14: 2.5 | S14: 133.31 | T14: 63.04 | U14: 355.26 | V14: 0 | W14: 49.63 | X14: 129.78 | Y14: 0 | Z14: 0 | AA14: 0 | AB14: 407.6 | AC14: 0 | AD14: 0 | AE14: =SUM(D14:AD14) -> 5570.39 | AG14: 45757 | AH14: thu | AI14: =AE14-AK14 -> 3565.0496 | AK14: 2005.3404
B15: 45758 | C15: fri | D15: 515.89 | E15: 637.9 | F15: 929.54 | G15: 396 | H15: 24.84 | I15: 207.75 | J15: 0 | K15: 231.04 | L15: 341.05 | M15: 274.46 | N15: 779.9 | O15: 0 | P15: 0 | Q15: 170.17 | R15: 253.6 | S15: 0.32 | T15: 3.96 | U15: 351.69 | V15: 0 | W15: 48.04 | X15: 129.34 | Y15: 0 | Z15: 0 | AA15: 0 | AB15: 241.08 | AC15: 0 | AD15: 0 | AE15: =SUM(D15:AD15) -> 5536.57 | AG15: 45758 | AH15: fri | AI15: =AE15-AK15 -> 3543.4048 | AK15: 1993.1652
B16: 45759 | C16: sat | D16: 427.11 | E16: 666.09 | F16: 1033.73 | G16: 401.93 | H16: 27.9 | I16: 117.5 | J16: 0 | K16: 182.02 | L16: 313.47 | M16: 601.18 | N16: 970.05 | O16: 0 | P16: 0 | Q16: 263.88 | R16: 226.07 | S16: 0 | T16: 4.86 | U16: 351.84 | V16: 0 | W16: 33.76 | X16: 129.64 | Y16: 0 | Z16: 0 | AA16: 0 | AB16: 0 | AC16: 0 | AD16: 0 | AE16: =SUM(D16:AD16) -> 5751.03 | AG16: 45759 | AH16: sat | AI16: =AE16-AK16 -> 3680.6592 | AK16: 2070.3708
... B34: 45777 | C34: wed | D34: 2.24 | E34: 583.75 | F34: 793.86 | G34: 379.66 | H34: 24.2 | I34: 96.58 | J34: 0 | K34: 202.01 | L34: 453.17 | M34: 106.09 | N34: 786.3 | O34: 0 | P34: 0 | Q34: 190.2 | R34: 140.71 | S34: 0 | T34: 3.68 | U34: 299.235 | V34: 2 | W34: 37.91 | X34: 81.46 | Y34: 0 | Z34: 0 | AA34: 0 | AB34: 0 | AC34: 0 | AD34: 0 | AE34: =SUM(D34:AD34) -> 4183.055 | AG34: 45777 | AH34: wed | AI34: =AE34-AK34 -> 2677.1552 | AK34: 1505.8998
AE35: =SUM(D35:AD35) -> 0 | AI35: =AE35-AK35 -> 0
B36: Total | D36: =SUM(D5:D35) -> 6831.91 | E36: =SUM(E5:E35) -> 16474.35 | F36: =SUM(F5:F35) -> 24592.9 | G36: =SUM(G5:G35) -> 13107.31 | H36: =SUM(H5:H35) -> 700.13 | I36: =SUM(I5:I35) -> 5119.49 | J36: =SUM(J5:J35) -> 0 | K36: =SUM(K5:K35) -> 5831.34 | ... AF36: =SUM(AF5:AF35) -> 0 | AH36: =SUM(AH5:AH35) -> 0 | AI36: =SUM(AI5:AI35) -> 90072.611 | AJ36: =SUM(AJ5:AJ35) -> 0 | AK36: =SUM(AK5:AK35) -> 50665.844
AD39: =28758-AI36 -> -61314.611

Sheet Machines Pump & inj
G2: =0.00000133*80 -> 0.0001064
C4: Main Building Split up
C5: Date | E5: Pump Stream | S5: Injector Stream
D6: Day | E6: Pump Assembly | F6: Barrel Hard Stage | G6: Barrel Soft Sage | H6: Small Parts (Phase-3) | I6: Sub assembly | J6: Aluminium Cell | K6: CAM Ring Cell | L6: Filter cell, ID Stores, AM Ware House | M6: Barrel Soft Washing Machine | N6: CAM Roller Shoe | O6: Phase-4 | P6: 6th BAY | Q6: Rotor cell | R6: Total | S6: BDN Nozzle Hard | T6: Injector assembly | U6: VCO | V6: NHB Hard Line | W6: Nozzle soft (Heat trt area) | X6: Total | Y6: Total | Z6: Main building only
C7: 45748 | D7: tue | E7: 232.45 | F7: 222.58 | G7: 209.5 | H7: 144.58 | I7: 86.3 | J7: 251.05 | K7: 44.06 | L7: 58.38 | M7: 239.93 | N7: 89.6 | O7: 143.38 | P7: 9.86 | Q7: 0 | R7: =SUM(E7:Q7) -> 1731.67 | S7: 156.17 | T7: 233.51 | U7: 603.65 | V7: 537.19 | W7: ='units overall'!I5 -> 299.1 | X7: =SUM(S7:W7) -> 1829.62 | Y7: =R7+X7 -> 3561.29 | Z7: =Y7-W7 -> 3262.19
C8: 45749 | D8: wed | E8: 407.49 | F8: 634.12 | G8: 459.36 | H8: 283.89 | I8: 140.08 | J8: 486.84 | K8: 99.54 | L8: 59.93 | M8: 569.09 | N8: 309.89 | O8: 374.18 | P8: 316.67 | Q8: 0 | R8: =SUM(E8:Q8) -> 4141.08 | S8: 389.98 | T8: 362.58 | U8: 1260.29 | V8: 1103.8 | W8: ='units overall'!I6 -> 569.68 | X8: =SUM(S8:W8) -> 3686.33 | Y8: =R8+X8 -> 7827.41 | Z8: =Y8-W8 -> 7257.73
C9: 45750 | D9: thu | E9: 495.17 | F9: 582.79 | G9: 599.11 | H9: 449.72 | I9: 129.17 | J9: 493.69 | K9: 487.81 | L9: 73.13 | M9: 643.49 | N9: 368.38 | O9: 596.01 | P9: 333.5 | Q9: 0 | R9: =SUM(E9:Q9) -> 5251.97 | S9: 379.1 | T9: 336.04 | U9: 1365.75 | V9: 1409.17 | W9: ='units overall'!I7 -> 696.35 | X9: =SUM(S9:W9) -> 4186.41 | Y9: =R9+X9 -> 9438.38 | Z9: =Y9-W9 -> 8742.03
C10: 45751 | D10: fri | E10: 441.92 | F10: 621.07 | G10: 621.06 | H10: 565.68 | I10: 152.35 | J10: 475.03 | K10: 894.67 | L10: 132.78 | M10: 583.94 | N10: 489.22 | O10: 615.04 | P10: 314.63 | Q10: 0 | R10: =SUM(E10:Q10) -> 5907.39 | S10: 394.15 | T10: 365.51 | U10: 1551.78 | V10: 1569.44 | W10: ='units overall'!I8 -> 644.17 | X10: =SUM(S10:W10) -> 4525.05 | Y10: =R10+X10 -> 10432.44 | Z10: =Y10-W10 -> 9788.27
C11: 45752 | D11: sat | E11: 500.67 | F11: 306.39 | G11: 604.67 | H11: 717.65 | I11: 139.41 | J11: 500.87 | K11: 890.14 | L11: 129.38 | M11: 560 | N11: 434.68 | O11: 674.73 | P11: 277.56 | Q11: 0 | R11: =SUM(E11:Q11) -> 5736.15 | S11: 388.22 | T11: 383.74 | U11: 1505.24 | V11: 1613.06 | W11: ='units overall'!I9 -> 658.68 | X11: =SUM(S11:W11) -> 4548.94 | Y11: =R11+X11 -> 10285.09 | Z11: =Y11-W11 -> 9626.41
C12: 45753 | D12: sun | E12: 226.56 | F12: 461.69 | G12: 116.38 | H12: 115.4 | I12: 26.53 | J12: 189.75 | K12: 18.01 | L12: 35.46 | M12: 339.07 | N12: 212.48 | O12: 192.23 | P12: 227.52 | Q12: 0 | R12: =SUM(E12:Q12) -> 2161.08 | S12: 5.93 | T12: 84.39 | U12: 90.97 | V12: 79.08 | W12: ='units overall'!I10 -> 16.59 | X12: =SUM(S12:W12) -> 276.96 | Y12: =R12+X12 -> 2438.04 | Z12: =Y12-W12 -> 2421.45
C13: 45754 | D13: mon | E13: 522.94 | F13: 804.2 | G13: 694.56 | H13: 757.7 | I13: 123.73 | J13: 499.94 | K13: 504.28 | L13: 119.75 | M13: 606.4 | N13: 423.04 | O13: 861.3 | P13: 291.14 | Q13: 0 | R13: =SUM(E13:Q13) -> 6208.98 | S13: 314.31 | T13: 402.49 | U13: 1579.63 | V13: 1607.94 | W13: ='units overall'!I11 -> 682.58 | X13: =SUM(S13:W13) -> 4586.95 | Y13: =R13+X13 -> 10795.93 | Z13: =Y13-W13 -> 10113.35
C14: 45755 | D14: tue | E14: 483.97 | F14: 718.98 | G14: 715.2 | H14: 707.55 | I14: 129.12 | J14: 411.09 | K14: 371.42 | L14: 142.1 | M14: 642.44 | N14: 408.07 | O14: 676.88 | P14: 349.76 | Q14: 0 | R14: =SUM(E14:Q14) -> 5756.58 | S14: 409.47 | T14: 399.35 | U14: 1510.93 | V14: 1632.38 | W14: ='units overall'!I12 -> 663.38 | X14: =SUM(S14:W14) -> 4615.51 | Y14: =R14+X14 -> 10372.09 | Z14: =Y14-W14 -> 9708.71
C15: 45756 | D15: wed | E15: 548.8 | F15: 732.84 | G15: 611.17 | H15: 731.14 | I15: 117.94 | J15: 464.98 | K15: 587.09 | L15: 144.06 | M15: 620.92 | N15: 473.21 | O15: 588.82 | P15: 356.35 | Q15: 0 | R15: =SUM(E15:Q15) -> 5977.32 | S15: 400.46 | T15: 419.2 | U15: 1580.81 | V15: 1685.18 | W15: ='units overall'!I13 -> 653.42 | X15: =SUM(S15:W15) -> 4739.07 | Y15: =R15+X15 -> 10716.39 | Z15: =Y15-W15 -> 10062.97
C16: 45757 | D16: thu | E16: 502.72 | F16: 725.95 | G16: 654.75 | H16: 712.15 | I16: 122.03 | J16: 525.04 | K16: 485.84 | L16: 137.16 | M16: 621.96 | N16: 494.85 | O16: 780.01 | P16: 349.76 | Q16: 0 | R16: =SUM(E16:Q16) -> 6112.22 | S16: 396.26 | T16: 385.62 | U16: 1637.2 | V16: 1732.17 | W16: ='units overall'!I14 -> 722.13 | X16: =SUM(S16:W16) -> 4873.38 | Y16: =R16+X16 -> 10985.6 | Z16: =Y16-W16 -> 10263.47
C17: 45758 | D17: fri | E17: 421.76 | F17: 723.2 | G17: 742.25 | H17: 747.4 | I17: 119.33 | J17: 475.53 | K17: 543.4 | L17: 83.37 | M17: 609.69 | N17: 428.8 | O17: 798.35 | P17: 339.71 | Q17: 0 | R17: =SUM(E17:Q17) -> 6032.79 | S17: 394.81 | T17: 329.38 | U17: 1618.79 | V17: 1648.33 | W17: ='units overall'!I15 -> 680.21 | X17: =SUM(S17:W17) -> 4671.52 | Y17: =R17+X17 -> 10704.31 | Z17: =Y17-W17 -> 10024.1
C18: 45759 | D18: sat | E18: 457.47 | F18: 388.67 | G18: 681.63 | H18: 675.04 | I18: 107.06 | J18: 371.9 | K18: 580.42 | L18: 135.78 | M18: 468.8 | N18: 388.87 | O18: 734.92 | P18: 209.67 | Q18: 0 | R18: =SUM(E18:Q18) -> 5200.23 | S18: 210.53 | T18: 396.99 | U18: 1558.2 | V18: 1442.33 | W18: ='units overall'!I16 -> 626.85 | X18: =SUM(S18:W18) -> 4234.9 | Y18: =R18+X18 -> 9435.13 | Z18: =Y18-W18 -> 8808.28
... C36: 45777 | D36: wed | E36: 577.54 | F36: 909.98 | G36: 501.44 | H36: 473.65 | I36: 137.95 | J36: 313.41 | K36: 1014.49 | L36: 96.19 | M36: 484.86 | N36: 311.68 | O36: 154.72 | P36: 275.01 | Q36: 0 | R36: =SUM(E36:Q36) -> 5250.92 | S36: 200.37 | T36: 419.86 | U36: 1495.32 | V36: 1550.21 | W36: ='units overall'!I34 -> 731.98 | X36: =SUM(S36:W36) -> 4397.74 | Y36: =R36+X36 -> 9648.66 | Z36: =Y36-W36 -> 8916.68
R37: =SUM(E37:Q37) -> 0 | W37: ='units overall'!I35 -> 0 | X37: =SUM(S37:W37) -> 0 | Y37: =R37+X37 -> 0 | Z37: =Y37-W37 -> 0
C38: Total | E38: =SUM(E7:E37) -> 13943.43 | F38: =SUM(F7:F37) -> 18690.81 | G38: =SUM(G7:G37) -> 16024.55 | H38: =SUM(H7:H37) -> 16440.11 | I38: =SUM(I7:I37) -> 3506.93 | J38: =SUM(J7:J37) -> 11504.85 | K38: =SUM(K7:K37) -> 15548.54 | L38: =SUM(L7:L37) -> 3637.69 | ... Z38: =SUM(Z7:Z37) -> 245279.9
E41: =E28-E27 -> 32.01 | F41: =F28-F27 -> 20.79 | G41: =G28-G27 -> -31.13 | H41: =H28-H27 -> 132.2 | I41: =I28-I27 -> 8.19 | J41: =J28-J27 -> -56.99 | K41: =K28-K27 -> 69.01 | L41: =L28-L27 -> 25.56 | ... P41: =P28-P27 -> -82.95 | R41: =R28-R27 -> 296.07 | Y41: =Y28-Y27 -> 250.15
E44: =(E38/Y38)*100 -> 5.2999189 | F44: =(F38/Y38)*100 -> 7.1044053 | G44: =(G38/Y38)*100 -> 6.0909558 | H44: =(H38/Y38)*100 -> 6.2489108 | I44: =(I38/Y38)*100 -> 1.3329894 | J44: =(J38/Y38)*100 -> 4.373011 | K44: =(K38/Y38)*100 -> 5.9100237 | L44: =(L38/Y38)*100 -> 1.3826915 | M44: =(M38/Y38)*100 -> 5.8893347 | N44: =(N38/Y38)*100 -> 3.9813696 | O44: =(O38/Y38)*100 -> 6.5687434 | P44: =(P38/Y38)*100 -> 3.2212653 | R44: =(R38/Y38)*100 -> 57.403619 | Y44: =(Y38/Y38)*100 -> 100
E48: =AVERAGE(E8:E12,E14:E19,E21:E26,E28:E31) -> 477.26333 | F48: =AVERAGE(F8:F12,F14:F19,F21:F26,F28:F31) -> 620.47476 | G48: =AVERAGE(G8:G12,G14:G19,G21:G26,G28:G31) -> 566.19857 | H48: =AVERAGE(H8:H12,H14:H19,H21:H26,H28:H31) -> 588.69762 | I48: =AVERAGE(I8:I12,I14:I19,I21:I26,I28:I31) -> 118.70238 | J48: =AVERAGE(J8:J12,J14:J19,J21:J26,J28:J31) -> 410.45619 | K48: =AVERAGE(K8:K12,K14:K19,K21:K26,K28:K31) -> 537.89429 | L48: =AVERAGE(L8:L12,L14:L19,L21:L26,L28:L31) -> 129.78714 | ... P48: =AVERAGE(P8:P12,P14:P19,P21:P26,P28:P31) -> 300.87524 | R48: =AVERAGE(R8:R12,R14:R19,R21:R26,R28:R31) -> 5310.9157
E421: 1 | F421: 1 | G421: 1 | H421: 1 | I421: 1 | J421: 1 | K421: 1 | L421: 1 | M421: 4 | N421: 2 | O421: 6 | P421: 1 | R421: 2

Sheet HFO
B4: HFO units | E4: FUEL CONSUMPTION
B5: Date | C5: Day | D5: HFO units | E5: HFO Cons. | F5: HSD Cons. | G5: Used Diesel utilized from E&D
B6: 45748 | C6: tue | D6: ='DG Usage'!E6+'DG Usage'!G6 -> 0
B7: 45749 | C7: wed | D7: ='DG Usage'!E7+'DG Usage'!G7 -> 0
B8: 45750 | C8: thu | D8: ='DG Usage'!E8+'DG Usage'!G8 -> 0
B9: 45751 | C9: fri | D9: ='DG Usage'!E9+'DG Usage'!G9 -> 0
B10: 45752 | C10: sat | D10: ='DG Usage'!E10+'DG Usage'!G10 -> 0 | K10: `
B11: 45753 | C11: sun | D11: ='DG Usage'!E11+'DG Usage'!G11 -> 0
B12: 45754 | C12: mon | D12: ='DG Usage'!E12+'DG Usage'!G12 -> 0
B13: 45755 | C13: tue | D13: ='DG Usage'!E13+'DG Usage'!G13 -> 254
B14: 45756 | C14: wed | D14: ='DG Usage'!E14+'DG Usage'!G14 -> 0
B15: 45757 | C15: thu | D15: ='DG Usage'!E15+'DG Usage'!G15 -> 110.75
B16: 45758 | C16: fri | D16: ='DG Usage'!E16+'DG Usage'!G16 -> 9766.75
B17: 45759 | C17: sat | D17: ='DG Usage'!E17+'DG Usage'!G17 -> 4515.25
B18: 45760 | C18: sun | D18: ='DG Usage'!E18+'DG Usage'!G18 -> 398
B19: 45761 | C19: mon | D19: ='DG Usage'!E19+'DG Usage'!G19 -> 0
B20: 45762 | C20: tue | D20: ='DG Usage'!E20+'DG Usage'!G20 -> 0
B21: 45763 | C21: wed | D21: ='DG Usage'!E21+'DG Usage'!G21 -> 2903
B22: 45764 | C22: thu | D22: ='DG Usage'!E22+'DG Usage'!G22 -> 0
... B35: 45777 | C35: wed | D35: ='DG Usage'!E35+'DG Usage'!G35 -> 45
B37: Total | D37: =SUM(D6:D36) -> 25165.75 | E37: =SUM(E6:E36) -> 0 | F37: =SUM(F6:F36) -> 0 | G37: =SUM(G6:G36) -> 0

Sheet HSD
B4: Date | C4: Day | D4: HSD units | E4: HSD Cons.
B6: 45748 | C6: tue | D6: ='DG Usage'!I6+'DG Usage'!K6+'DG Usage'!M6+'DG Usage'!O6 -> 0
B7: 45749 | C7: wed | D7: ='DG Usage'!I7+'DG Usage'!K7+'DG Usage'!M7+'DG Usage'!O7 -> 0
B8: 45750 | C8: thu | D8: ='DG Usage'!I8+'DG Usage'!K8+'DG Usage'!M8+'DG Usage'!O8 -> 0
B9: 45751 | C9: fri | D9: ='DG Usage'!I9+'DG Usage'!K9+'DG Usage'!M9+'DG Usage'!O9 -> 0
B10: 45752 | C10: sat | D10: ='DG Usage'!I10+'DG Usage'!K10+'DG Usage'!M10+'DG Usage'!O10 -> 0
B11: 45753 | C11: sun | D11: ='DG Usage'!I11+'DG Usage'!K11+'DG Usage'!M11+'DG Usage'!O11 -> 0
B12: 45754 | C12: mon | D12: ='DG Usage'!I12+'DG Usage'!K12+'DG Usage'!M12+'DG Usage'!O12 -> 0
B13: 45755 | C13: tue | D13: ='DG Usage'!I13+'DG Usage'!K13+'DG Usage'!M13+'DG Usage'!O13 -> 556
B14: 45756 | C14: wed | D14: ='DG Usage'!I14+'DG Usage'!K14+'DG Usage'!M14+'DG Usage'!O14 -> 0
B15: 45757 | C15: thu | D15: ='DG Usage'!I15+'DG Usage'!K15+'DG Usage'!M15+'DG Usage'!O15 -> 93.44
B16: 45758 | C16: fri | D16: ='DG Usage'!I16+'DG Usage'!K16+'DG Usage'!M16+'DG Usage'!O16 -> 18265.13
B17: 45759 | C17: sat | D17: ='DG Usage'!I17+'DG Usage'!K17+'DG Usage'!M17+'DG Usage'!O17 -> 10702.27
... B35: 45777 | C35: wed | D35: ='DG Usage'!I35+'DG Usage'!K35+'DG Usage'!M35+'DG Usage'!O35 -> 13
B37: Total | D37: =SUM(D6:D36) -> 46680.92 | E37: =E6 -> 0
H76: stock based(dip rod)
H77: 1st Jan-20 | I77: 4087 | K77: =9*230 -> 2070 | N77: CANTEEN BOILER
H78: Received | I78: 12000 | J78: =I78*69.14 -> 829680 | N78: E&D TESTING
I79: =SUM(I77:I78) -> 16087 | N79: E&D DG SET
H80: 1st Jan-20 | I80: 4087 | N80: E.T.P
H81: Total consumption | I81: =I79-I80 -> 12000 | N81: FORK LIFT
H82: Canteen | I82: 9050 | J82: Ltrs | M82: Diesel issued to other departments
H83: E&D Testing | I83: 0 | J83: Ltrs | M83: Area | N83: QTY
H84: Fork Lift | I84: 120 | J84: Ltrs | M84: Canteen | N84: =I82 -> 9050 | O84: Ltrs
H85: ETP | I85: 0 | J85: Ltrs | M85: E&D Testing | N85: =I83 -> 0 | O85: Ltrs
H86: Others | I86: 90 | J86: Ltrs | M86: Fork Lift | N86: =I84 -> 120 | O86: Ltrs
H87: DG set Con | I87: =I81-I82-I83-I84-I85-I86 -> 2740 | M87: ETP | N87: =I85 -> 0 | O87: Ltrs
H88: From E&D Tank for power house DG set | I88: 0 | M88: Lube oil castrol | N88: 0 | O88: Ltrs
H89: From E&D Tank for E&D DG set | I89: 0 | M89: Lube oil Shell | N89: 36 | O89: Ltrs
H90: hfo & hsd tank stock day tank
H91: DG set Con. | I91: =(I87-I90)+I88+I89 -> 2740
G206: Date | H206: 43391 | I206: 43422
G207: 1 | H207: 230 | I207: 690
G208: 2 | H208: 0 | I208: 460
G209: 3 | H209: 460 | I209: 460
G210: 4 | H210: 460 | I210: 0
G211: 5 | H211: 460 | I211: 230
G212: 6 | H212: 460 | I212: 0
G213: 7 | H213: 0 | I213: 0
G214: 8 | H214: 460 | I214: 0
...

Sheet DG Usage
B3: HFO DG | H3: HSD DG | CH3: RH | CJ3: kWh
B4: DG Name | D4: 1.9 MW | F4: 1 MW | H4: DG - I 1000KVA | J4: * DG - II 1500KVA (New Rental DG - Modern ) | L4: * 1500 KVA (Old Rental DG- Powerica) | N4: * 750 KVA (E&D - Modern) | AZ4: * 750 KVA (E&D - Modern) | BC4: * 750 KVA (E&D - Modern) | BI4: *1500 KVA ( Modern) | BK4: *1500 KVA ( Modern) | BN4: *1500 KVA ( Powerica) | BP4: *1500 KVA ( Powerica) | BS4: 1000 KVA | BU4: 1000 KVA | CB4: 1.9MW | CH4: 1 MW | CN4: 1250 | CT4: 1500 | CZ4: 1000 KVA-1 | DF4: 1500 dg 2
B5: Date | D5: RH | E5: Units | F5: RH | G5: Units | H5: RH | I5: Units | J5: RH | K5: Units | L5: RH | M5: Units | N5: RH | O5: Units | AH5: s | AI5: 1.9 | AK5: s d | AL5: 1000 | AO5: 1500 M | AR5: 1500 P | AZ5: units | BA5: meter reading | BC5: RH | BD5: meter reading | BI5: units | BJ5: meter reading | BK5: RH | BL5: meter reading | BN5: units | BO5: meter reading | BP5: RH | BQ5: meter reading | BS5: units | BT5: meter reading | BU5: RH | BV5: meter reading | CB5: RH | CC5: Units | CD5: RH | CE5: Units | CH5: RH | CI5: Units | CJ5: RH | CK5: Units | CN5: RH | CO5: Units | CP5: RH | CQ5: Units | CT5: RH | CU5: Units | CV5: RH | CW5: Units | CZ5: RH | DA5: Units | DB5: RH | DC5: Units | DF5: RH | DG5: Units | DH5: RH | DI5: Units
B6: 45748 | C6: tue | D6: 0 | E6: 0 | F6: 0 | G6: 0 | H6: 0 | I6: 0 | J6: 0 | K6: 0 | L6: 0 | M6: 0 | N6: 0 | O6: 0 | AH6: 1789.88 | AI6: 1790 | AJ6: =AI6-E6 -> 1790 | AK6: =AI6-AH6 -> 0.12 | AL6: 0 | AM6: =AL6-I6 -> 0 | AO6: 1077 | AP6: =AO6-K6 -> 1077 | AR6: 0 | AS6: =AR6-M6 -> 0 | AZ6: =(BA7-BA6)*240 -> 1944 | BA6: 2702.8 | BC6: =(BD7-BD6)*60 -> 546 | BD6: 2421.8 | BE6: =BC6/60 -> 9.1 | BH6: 1 | BI6: =(BJ7-BJ6) -> 4 | BJ6: 1777341 | BK6: =(BL7-BL6)*60 -> 12 | BL6: 4620.6 | BN6: =(BO7-BO6) -> -2421.8 | BO6: 2421.8 | BP6: =(BQ7-BQ6)*60 -> -145308 | BQ6: 2421.8 | BS6: =(BT7-BT6) -> -2421.8 | BT6: 2421.8 | BU6: =(BV7-BV6)*60 -> -145308 | BV6: 2421.8 | CA6: 1 | CB6: 71626.45 | CC6: 777165 | CD6: =(CB7-CB6)*60 -> 0 | CE6: =CC7-CC6 -> 0 | CG6: 1 | CH6: 33529.3 | CI6: 596657 | CJ6: =(CH7-CH6)*60 -> 0 | CK6: =(CI7-CI6) -> 0 | CM6: 1 | CN6: 597.2 | CO6: 261183 | CP6: =(CN7-CN6)*60 -> 0 | CQ6: =(CO7-CO6) -> 0 | CS6: 1 | CT6: 8399.9 | CU6: 864599 | CV6: =(CT7-CT6)*60 -> 0 | CW6: =(CU7-CU6) -> 0 | CY6: 1 | CZ6: 1114 | DA6: 432331 | DB6: =(CZ7-CZ6)*60 -> 0 | DC6: =(DA7-DA6) -> 17 | DE6: 1 | DF6: 3961.7 | DG6: 1430631 | DH6: =(DF7-DF6)*60 -> 0 | DI6: =(DG7-DG6) -> 0
B7: 45749 | C7: wed | D7: 0 | E7: 0 | F7: 0 | G7: 0 | H7: 0 | I7: 0 | J7: 0 | K7: 0 | L7: 0 | M7: 0 | N7: 0 | O7: 0 | AH7: 2804.25 | AI7: 2800 | AJ7: =AI7-E7 -> 2800 | AK7: =AI7-AH7 -> -4.25 | AL7: 1062 | AM7: =AL7-I7 -> 1062 | AO7: 1744 | AP7: =AO7-K7 -> 1744 | AR7: 1444 | AS7: =AR7-M7 -> 1444 | AZ7: =(BA8-BA7)*240 -> 1704 | BA7: 2710.9 | BC7: =(BD8-BD7)*60 -> 264 | BD7: 2430.9 | BE7: =BC7/60 -> 4.4 | BH7: 2 | BI7: =(BJ8-BJ7) -> 0 | BJ7: 1777345 | BK7: =(BL8-BL7)*60 -> 162 | BL7: 4620.8 | BN7: =(BO8-BO7) -> 0 | BP7: =(BQ8-BQ7)*60 -> 0 | BS7: =(BT8-BT7) -> 0 | BU7: =(BV8-BV7)*60 -> 0 | CA7: 2 | CB7: 71626.45 | CC7: 777165 | CD7: =(CB8-CB7)*60 -> 0 | CE7: =CC8-CC7 -> 0 | CG7: 2 | CH7: 33529.3 | CI7: 596657 | CJ7: =(CH8-CH7)*60 -> 18 | CK7: =(CI8-CI7) -> 0 | CM7: 2 | CN7: 597.2 | CO7: 261183 | CP7: =(CN8-CN7)*60 -> 72 | CQ7: =(CO8-CO7) -> 316 | CS7: 2 | CT7: 8399.9 | CU7: 864599 | CV7: =(CT8-CT7)*60 -> 60 | CW7: =(CU8-CU7) -> 668 | CY7: 2 | CZ7: 1114 | DA7: 432348 | DB7: =(CZ8-CZ7)*60 -> 60 | DC7: =(DA8-DA7) -> 239 | DE7: 2 | DF7: 3961.7 | DG7: 1430631 | DH7: =(DF8-DF7)*60 -> 72 | DI7: =(DG8-DG7) -> 224
B8: 45750 | C8: thu | D8: 0 | E8: 0 | F8: 0 | G8: 0 | H8: 0 | I8: 0 | J8: 0 | K8: 0 | L8: 0 | M8: 0 | N8: 0 | O8: 0 | AH8: 4503 | AI8: 4500 | AJ8: =AI8-E8 -> 4500 | AK8: =AI8-AH8 -> -3 | AL8: 1596 | AM8: =AL8-I8 -> 1596 | AO8: 3242 | AP8: =AO8-K8 -> 3242 | AR8: 2030 | AS8: =AR8-M8 -> 2030 | AZ8: =(BA9-BA8)*240 -> 1824 | BA8: 2718 | BC8: =(BD9-BD8)*60 -> 0 | BD8: 2435.3 | BE8: =BC8/60 -> 0 | BH8: 3 | BI8: =(BJ9-BJ8) -> 1077 | BJ8: 1777345 | BK8: =(BL9-BL8)*60 -> 210 | BL8: 4623.5 | BN8: =(BO9-BO8) -> 0 | BP8: =(BQ9-BQ8)*60 -> 0 | BS8: =(BT9-BT8) -> 0 | BU8: =(BV9-BV8)*60 -> 0 | CA8: 3 | CB8: 71626.45 | CC8: 777165 | CD8: =(CB9-CB8)*60 -> 0 | CE8: =CC9-CC8 -> 0 | CG8: 3 | CH8: 33529.6 | CI8: 596657 | CJ8: =(CH9-CH8)*60 -> 66 | CK8: =(CI9-CI8) -> 41 | CM8: 3 | CN8: 598.4 | CO8: 261499 | CP8: =(CN9-CN8)*60 -> 0 | CQ8: =(CO9-CO8) -> 0 | CS8: 3 | CT8: 8400.9 | CU8: 865267 | CV8: =(CT9-CT8)*60 -> 0 | CW8: =(CU9-CU8) -> 0 | CY8: 3 | CZ8: 1115 | DA8: 432587 | DB8: =(CZ9-CZ8)*60 -> 0 | DC8: =(DA9-DA8) -> 0 | DE8: 3 | DF8: 3962.9 | DG8: 1430855 | DH8: =(DF9-DF8)*60 -> 0 | DI8: =(DG9-DG8) -> 0
B9: 45751 | C9: fri | D9: 0 | E9: 0 | F9: 0 | G9: 0 | H9: 0 | I9: 0 | J9: 0 | K9: 0 | L9: 0 | M9: 0 | N9: 0 | O9: 0 | AH9: 88.25 | AI9: 90 | AJ9: =AI9-E9 -> 90 | AK9: =AI9-AH9 -> 1.75 | AL9: 2444 | AM9: =AL9-I9 -> 2444 | AO9: 568 | AP9: =AO9-K9 -> 568 | AR9: 3862 | AS9: =AR9-M9 -> 3862 | AZ9: =(BA10-BA9)*240 -> 0 | BA9: 2725.6 | BC9: =(BD10-BD9)*60 -> 0 | BD9: 2435.3 | BE9: =BC9/60 -> 0 | BH9: 4 | BI9: =(BJ10-BJ9) -> 1744 | BJ9: 1778422 | BK9: =(BL10-BL9)*60 -> 264 | BL9: 4627 | BN9: =(BO10-BO9) -> 0 | BP9: =(BQ10-BQ9)*60 -> 0 | BS9: =(BT10-BT9) -> 0 | BU9: =(BV10-BV9)*60 -> 0 | CA9: 4 | CB9: 71626.45 | CC9: 777165 | CD9: =(CB10-CB9)*60 -> 0 | CE9: =CC10-CC9 -> 0 | CG9: 4 | CH9: 33530.7 | CI9: 596698 | CJ9: =(CH10-CH9)*60 -> 0 | CK9: =(CI10-CI9) -> 0 | CM9: 4 | CN9: 598.4 | CO9: 261499 | CP9: =(CN10-CN9)*60 -> 0 | CQ9: =(CO10-CO9) -> 0 | CS9: 4 | CT9: 8400.9 | CU9: 865267 | CV9: =(CT10-CT9)*60 -> 0 | CW9: =(CU10-CU9) -> 0 | CY9: 4 | CZ9: 1115 | DA9: 432587 | DB9: =(CZ10-CZ9)*60 -> 0 | DC9: =(DA10-DA9) -> 0 | DE9: 4 | DF9: 3962.9 | DG9: 1430855 | DH9: =(DF10-DF9)*60 -> 0 | DI9: =(DG10-DG9) -> 0
B10: 45752 | C10: sat | D10: 0 | E10: 0 | F10: 0 | G10: 0 | H10: 0 | I10: 0 | J10: 0 | K10: 0 | L10: 0 | M10: 0 | N10: 0 | O10: 0 | AH10: 0 | AI10: 0 | AJ10: =AI10-E10 -> 0 | AK10: =AI10-AH10 -> 0 | AL10: 0 | AM10: =AL10-I10 -> 0 | AO10: 3 | AP10: =AO10-K10 -> 3 | AR10: 387 | AS10: =AR10-M10 -> 387 | AZ10: =(BA11-BA10)*240 -> 0 | BA10: 2725.6 | BC10: =(BD11-BD10)*60 -> 0 | BD10: 2435.3 | BE10: =BC10/60 -> 0 | BH10: 5 | BI10: =(BJ11-BJ10) -> 3242 | BJ10: 1780166 | BK10: =(BL11-BL10)*60 -> 144 | BL10: 4631.4 | BN10: =(BO11-BO10) -> 0 | BP10: =(BQ11-BQ10)*60 -> 0 | BS10: =(BT11-BT10) -> 0 | BU10: =(BV11-BV10)*60 -> 0 | CA10: 5 | CB10: 71626.45 | CC10: 777165 | CD10: =(CB11-CB10)*60 -> 0 | CE10: =CC11-CC10 -> 0 | CG10: 5 | CH10: 33530.7 | CI10: 596698 | CJ10: =(CH11-CH10)*60 -> 36 | CK10: 200 | CM10: 5 | CN10: 598.4 | CO10: 261499 | CP10: =(CN11-CN10)*60 -> 36 | CQ10: =(CO11-CO10) -> 66 | CS10: 5 | CT10: 8400.9 | CU10: 865267 | CV10: =(CT11-CT10)*60 -> 30 | CW10: =(CU11-CU10) -> 72 | CY10: 5 | CZ10: 1115 | DA10: 432587 | DB10: =(CZ11-CZ10)*60 -> 0 | DC10: =(DA11-DA10) -> 48 | DE10: 5 | DF10: 3962.9 | DG10: 1430855 | DH10: =(DF11-DF10)*60 -> 36 | DI10: =(DG11-DG10) -> 112
B11: 45753 | C11: sun | D11: 0 | E11: 0 | F11: 0 | G11: 0 | H11: 0 | I11: 0 | J11: 0 | K11: 0 | L11: 0 | M11: 0 | N11: 0 | O11: 0 | AH11: 1094.63 | AI11: 856 | AJ11: =AI11-E11 -> 856 | AK11: =AI11-AH11 -> -238.63 | AL11: 0 | AM11: =AL11-I11 -> 0 | AO11: 790 | AP11: =AO11-K11 -> 790 | AR11: 0 | AS11: =AR11-M11 -> 0 | AZ11: =(BA12-BA11)*240 -> 1008 | BA11: 2725.6 | BC11: =(BD12-BD11)*60 -> 306 | BD11: 2435.3 | BE11: =BC11/60 -> 5.1 | BH11: 6 | BI11: =(BJ12-BJ11) -> 568 | BJ11: 1783408 | BK11: =(BL12-BL11)*60 -> 12 | BL11: 4633.8 | BN11: =(BO12-BO11) -> 0 | BP11: =(BQ12-BQ11)*60 -> 0 | BS11: =(BT12-BT11) -> 0 | BU11: =(BV12-BV11)*60 -> 0 | CA11: 6 | CB11: 71626.45 | CC11: 777165 | CD11: =(CB12-CB11)*60 -> 0 | CE11: =CC12-CC11 -> 0 | CG11: 6 | CH11: 33531.3 | CI11: 596698 | CJ11: =(CH12-CH11)*60 -> -2011878 | CK11: =(CI12-CI11) -> -596698 | CM11: 6 | CN11: 599 | CO11: 261565 | CP11: =(CN12-CN11)*60 -> -35940 | CQ11: =(CO12-CO11) -> -261565 | CS11: 6 | CT11: 8401.4 | CU11: 865339 | CV11: =(CT12-CT11)*60 -> -504084 | CW11: =(CU12-CU11) -> -865339 | CY11: 6 | CZ11: 1115 | DA11: 432635 | DB11: =(CZ12-CZ11)*60 -> -66900 | DC11: =(DA12-DA11) -> -432635 | DE11: 6 | DF11: 3963.5 | DG11: 1430967 | DH11: =(DF12-DF11)*60 -> -237810 | DI11: =(DG12-DG11) -> -1430967
B12: 45754 | C12: mon | D12: 0 | E12: 0 | F12: 0 | G12: 0 | H12: 0 | I12: 0 | J12: 0 | K12: 0 | L12: 0 | M12: 0 | N12: 0 | O12: 0 | AH12: 3057.25 | AI12: 2843 | AJ12: =AI12-E12 -> 2843 | AK12: =AI12-AH12 -> -214.25 | AL12: 672 | AM12: =AL12-I12 -> 672 | AO12: 1844 | AP12: =AO12-K12 -> 1844 | AR12: 953 | AS12: =AR12-M12 -> 953 | AZ12: =(BA13-BA12)*240 -> 1296 | BA12: 2729.8 | BC12: =(BD13-BD12)*60 -> 552 | BD12: 2440.4 | BE12: =BC12/60 -> 9.2 | BH12: 7 | BI12: =(BJ13-BJ12) -> 3 | BJ12: 1783976 | BK12: =(BL13-BL12)*60 -> 90 | BL12: 4634 | BN12: =(BO13-BO12) -> 0 | BP12: =(BQ13-BQ12)*60 -> 0 | BS12: =(BT13-BT12) -> 0 | BU12: =(BV13-BV12)*60 -> 0 | CA12: 7 | CB12: 71626.45 | CC12: 777165 | CD12: =(CB13-CB12)*60 -> 0 | CE12: =CC13-CC12 -> 0 | CG12: 7 | CJ12: =(CH13-CH12)*60 -> 0 | CK12: =(CI13-CI12) -> 0 | CM12: 7 | CP12: =(CN13-CN12)*60 -> 0 | CQ12: =(CO13-CO12) -> 0 | CS12: 7 | CV12: =(CT13-CT12)*60 -> 0 | CW12: =(CU13-CU12) -> 0 | CY12: 7 | DB12: =(CZ13-CZ12)*60 -> 0 | DC12: =(DA13-DA12) -> 0 | DE12: 7 | DH12: =(DF13-DF12)*60 -> 0 | DI12: =(DG13-DG12) -> 0
B13: 45755 | C13: tue | D13: 10 | E13: 254 | F13: 0 | G13: 0 | H13: 10 | I13: 249 | J13: 10 | K13: 69 | L13: 10 | M13: 238 | N13: 0 | O13: 0 | AH13: 6314.63 | AI13: 6998 | AJ13: =AI13-E13 -> 6744 | AK13: =AI13-AH13 -> 683.37 | AL13: 1726 | AM13: =AL13-I13 -> 1477 | AO13: 5895 | AP13: =AO13-K13 -> 5826 | AR13: 2254 | AS13: =AR13-M13 -> 2016 | AZ13: =(BA14-BA13)*240 -> 2256 | BA13: 2735.2 | BC13: =(BD14-BD13)*60 -> 132 | BD13: 2449.6 | BE13: =BC13/60 -> 2.2 | BH13: 8 | BI13: =(BJ14-BJ13) -> 8529 | BJ13: 1783979 | BK13: =(BL14-BL13)*60 -> 198 | BL13: 4635.5 | BN13: =(BO14-BO13) -> 0 | BP13: =(BQ14-BQ13)*60 -> 0 | BS13: =(BT14-BT13) -> 0 | BU13: =(BV14-BV13)*60 -> 0 | CA13: 8 | CB13: 71626.45 | CC13: 777165 | CD13: =(CB14-CB13)*60 -> 0 | CE13: =CC14-CC13 -> 0 | CG13: 8 | CJ13: =(CH14-CH13)*60 -> 0 | CK13: =(CI14-CI13) -> 0 | CM13: 8 | CP13: =(CN14-CN13)*60 -> 0 | CQ13: =(CO14-CO13) -> 0 | CS13: 8 | CV13: =(CT14-CT13)*60 -> 0 | CW13: =(CU14-CU13) -> 0 | CY13: 8 | DB13: =(CZ14-CZ13)*60 -> 0 | DC13: =(DA14-DA13) -> 0 | DE13: 8 | DH13: =(DF14-DF13)*60 -> 0 | DI13: =(DG14-DG13) -> 0
B14: 45756 | C14: wed | D14: 0 | E14: 0 | F14: 0 | G14: 0 | H14: 0 | I14: 0 | J14: 0 | K14: 0 | L14: 0 | M14: 0 | N14: 0 | O14: 0 | AH14: 4151.38 | AI14: 3683 | AJ14: =AI14-E14 -> 3683 | AK14: =AI14-AH14 -> -468.38 | AL14: 1480 | AM14: =AL14-I14 -> 1480 | AO14: 2902 | AP14: =AO14-K14 -> 2902 | AR14: 5155 | AS14: =AR14-M14 -> 5155 | AZ14: =(BA15-BA14)*240 -> 1848 | BA14: 2744.6 | BC14: =(BD15-BD14)*60 -> 252 | BD14: 2451.8 | BE14: =BC14/60 -> 4.2 | BH14: 9 | BI14: =(BJ15-BJ14) -> 2902 | BJ14: 1792508 | BK14: =(BL15-BL14)*60 -> 570 | BL14: 4638.8 | BN14: =(BO15-BO14) -> 0 | BP14: =(BQ15-BQ14)*60 -> 0 | BS14: =(BT15-BT14) -> 0 | BU14: =(BV15-BV14)*60 -> 0 | CA14: 9 | CB14: 71626.45 | CC14: 777165 | CD14: =(CB15-CB14)*60 -> 0 | CE14: =CC15-CC14 -> 0 | CG14: 9 | CJ14: =(CH15-CH14)*60 -> 0 | CK14: =(CI15-CI14) -> 0 | CM14: 9 | CP14: =(CN15-CN14)*60 -> 0 | CQ14: =(CO15-CO14) -> 0 | CS14: 9 | CV14: =(CT15-CT14)*60 -> 0 | CW14: =(CU15-CU14) -> 0 | CY14: 9 | DB14: =(CZ15-CZ14)*60 -> 0 | DC14: =(DA15-DA14) -> 0 | DE14: 9 | DH14: =(DF15-DF14)*60 -> 0 | DI14: =(DG15-DG14) -> 0
B15: 45757 | C15: thu | D15: 10 | E15: 110.75 | F15: 0 | G15: 0 | H15: 0 | I15: 0 | J15: 0 | K15: 0 | L15: 10 | M15: 93.44 | N15: 0 | O15: 0 | AH15: 651.63 | AI15: 651 | AJ15: =AI15-E15 -> 540.25 | AK15: =AI15-AH15 -> -0.63 | AL15: 2590 | AM15: =AL15-I15 -> 2590 | AO15: 956 | AP15: =AO15-K15 -> 956 | AR15: 3809 | AS15: =AR15-M15 -> 3715.56 | AZ15: =(BA16-BA15)*240 -> 312 | BA15: 2752.3 | BC15: =(BD16-BD15)*60 -> 78 | BD15: 2456 | BE15: =BC15/60 -> 1.3 | BH15: 10 | BI15: =(BJ16-BJ15) -> 956 | BJ15: 1795410 | BK15: =(BL16-BL15)*60 -> 318 | BL15: 4648.3 | BN15: =(BO16-BO15) -> 0 | BP15: =(BQ16-BQ15)*60 -> 0 | BS15: =(BT16-BT15) -> 0 | BU15: =(BV16-BV15)*60 -> 0 | CA15: 10 | CB15: 71626.45 | CC15: 777165 | CD15: =(CB16-CB15)*60 -> 0 | CE15: =CC16-CC15 -> 0 | CG15: 10 | CJ15: =(CH16-CH15)*60 -> 0 | CK15: =(CI16-CI15) -> 0 | CM15: 10 | CP15: =(CN16-CN15)*60 -> 0 | CQ15: =(CO16-CO15) -> 0 | CS15: 10 | CV15: =(CT16-CT15)*60 -> 0 | CW15: =(CU16-CU15) -> 0 | CY15: 10 | DB15: =(CZ16-CZ15)*60 -> 0 | DC15: =(DA16-DA15) -> 0 | DE15: 10 | DH15: =(DF16-DF15)*60 -> 0 | DI15: =(DG16-DG15) -> 0
B16: 45758 | C16: fri | D16: 760 | E16: 9766.75 | F16: 0 | G16: 0 | H16: 760 | I16: 2685 | J16: 760 | K16: 9489 | L16: 760 | M16: 2661.12 | N16: 760 | O16: 3430.01 | AH16: 0 | AI16: 0 | AJ16: =AI16-E16 -> -9766.75 | AK16: =AI16-AH16 -> 0 | AL16: 723 | AM16: =AL16-I16 -> -1962 | AO16: 2 | AP16: =AO16-K16 -> -9487 | AR16: 1167 | AS16: =AR16-M16 -> -1494.12 | AZ16: =(BA17-BA16)*240 -> 0 | BA16: 2753.6 | BC16: =(BD17-BD16)*60 -> 0 | BD16: 2457.3 | BE16: =BC16/60 -> 0 | BH16: 11 | BI16: =(BJ17-BJ16) -> 2 | BJ16: 1796366 | BK16: =(BL17-BL16)*60 -> 120 | BL16: 4653.6 | BN16: =(BO17-BO16) -> 0 | BP16: =(BQ17-BQ16)*60 -> 0 | BS16: =(BT17-BT16) -> 0 | BU16: =(BV17-BV16)*60 -> 0 | CA16: 11 | CB16: 71626.45 | CC16: 777165 | CD16: =(CB17-CB16)*60 -> 0 | CE16: =CC17-CC16 -> 0 | CG16: 11 | CJ16: =(CH17-CH16)*60 -> 0 | CK16: =(CI17-CI16) -> 0 | CM16: 11 | CP16: =(CN17-CN16)*60 -> 0 | CQ16: =(CO17-CO16) -> 0 | CS16: 11 | CV16: =(CT17-CT16)*60 -> 0 | CW16: =(CU17-CU16) -> 0 | CY16: 11 | DB16: =(CZ17-CZ16)*60 -> 0 | DC16: =(DA17-DA16) -> 0 | DE16: 11 | DH16: =(DF17-DF16)*60 -> 0 | DI16: =(DG17-DG16) -> 0
B17: 45759 | C17: sat | D17: 240 | E17: 4515.25 | F17: 0 | G17: 0 | H17: 240 | I17: 2949 | J17: 240 | K17: 2734 | L17: 240 | M17: 3397.25 | N17: 240 | O17: 1622.02 | AH17: 0 | AI17: 0 | AJ17: =AI17-E17 -> -4515.25 | AK17: =AI17-AH17 -> 0 | AL17: 0 | AM17: =AL17-I17 -> -2949 | AO17: 3 | AP17: =AO17-K17 -> -2731 | AR17: 0 | AS17: =AR17-M17 -> -3397.25 | AZ17: =(BA18-BA17)*240 -> 0 | BA17: 2753.6 | BC17: =(BD18-BD17)*60 -> 0 | BD17: 2457.3 | BE17: =BC17/60 -> 0 | BH17: 12 | BI17: =(BJ18-BJ17) -> 3 | BJ17: 1796368 | BK17: =(BL18-BL17)*60 -> 6 | BL17: 4655.6 | BN17: =(BO18-BO17) -> 0 | BP17: =(BQ18-BQ17)*60 -> 0 | BS17: =(BT18-BT17) -> 0 | BU17: =(BV18-BV17)*60 -> 0 | CA17: 12 | CB17: 71626.45 | CC17: 777165 | CD17: =(CB18-CB17)*60 -> 0 | CE17: =CC18-CC17 -> 0 | CG17: 12 | CJ17: =(CH18-CH17)*60 -> 0 | CK17: =(CI18-CI17) -> 0 | CM17: 12 | CP17: =(CN18-CN17)*60 -> 0 | CQ17: =(CO18-CO17) -> 0 | CS17: 12 | CV17: =(CT18-CT17)*60 -> 0 | CW17: =(CU18-CU17) -> 0 | CY17: 12 | DB17: =(CZ18-CZ17)*60 -> 0 | DC17: =(DA18-DA17) -> 0 | DE17: 12 | DH17: =(DF18-DF17)*60 -> 0 | DI17: =(DG18-DG17) -> 0
B18: 45760 | C18: sun | D18: 60 | E18: 398 | F18: 0 | G18: 0 | H18: 0 | I18: 0 | J18: 60 | K18: 672 | L18: 60 | M18: 22.14 | N18: 60 | O18: 190.44 | AH18: 0 | AI18: 0 | AJ18: =AI18-E18 -> -398 | AK18: =AI18-AH18 -> 0 | AL18: 0 | AM18: =AL18-I18 -> 0 | AO18: 2 | AP18: =AO18-K18 -> -670 | AR18: 0 | AS18: =AR18-M18 -> -22.14 | AZ18: =(BA19-BA18)*240 -> 0 | BA18: 2753.6 | BC18: =(BD19-BD18)*60 -> 0 | BD18: 2457.3 | BE18: =BC18/60 -> 0 | BH18: 13 | BI18: =(BJ19-BJ18) -> 2 | BJ18: 1796371 | BK18: =(BL19-BL18)*60 -> 12 | BL18: 4655.7 | BN18: =(BO19-BO18) -> 0 | BP18: =(BQ19-BQ18)*60 -> 0 | BS18: =(BT19-BT18) -> 0 | BU18: =(BV19-BV18)*60 -> 0 | CA18: 13 | CB18: 71626.45 | CC18: 777165 | CD18: =(CB19-CB18)*60 -> 0 | CE18: =CC19-CC18 -> 0 | CG18: 13 | CJ18: =(CH19-CH18)*60 -> 0 | CK18: =(CI19-CI18) -> 0 | CM18: 13 | CP18: =(CN19-CN18)*60 -> 0 | CQ18: =(CO19-CO18) -> 0 | CS18: 13 | CV18: =(CT19-CT18)*60 -> 0 | CW18: =(CU19-CU18) -> 0 | CY18: 13 | DB18: =(CZ19-CZ18)*60 -> 0 | DC18: =(DA19-DA18) -> 0 | DE18: 13 | DH18: =(DF19-DF18)*60 -> 0 | DI18: =(DG19-DG18) -> 0
B19: 45761 | C19: mon | D19: 0 | E19: 0 | F19: 0 | G19: 0 | H19: 0 | I19: 0 | J19: 0 | K19: 0 | L19: 0 | M19: 0 | N19: 0 | O19: 0 | AH19: 0 | AI19: 0 | AJ19: =AI19-E19 -> 0 | AK19: =AI19-AH19 -> 0 | AL19: 0 | AM19: =AL19-I19 -> 0 | AO19: 3 | AP19: =AO19-K19 -> 3 | AR19: 0 | AS19: =AR19-M19 -> 0 | AZ19: =(BA20-BA19)*240 -> 0 | BA19: 2753.6 | BC19: =(BD20-BD19)*60 -> 0 | BD19: 2457.3 | BE19: =BC19/60 -> 0 | BH19: 14 | BI19: =(BJ20-BJ19) -> 3 | BJ19: 1796373 | BK19: =(BL20-BL19)*60 -> 12 | BL19: 4655.9 | BN19: =(BO20-BO19) -> 0 | BP19: =(BQ20-BQ19)*60 -> 0 | BS19: =(BT20-BT19) -> 0 | BU19: =(BV20-BV19)*60 -> 0 | CA19: 14 | CB19: 71626.45 | CC19: 777165 | CD19: =(CB20-CB19)*60 -> 0 | CE19: =CC20-CC19 -> 0 | CG19: 14 | CJ19: =(CH20-CH19)*60 -> 0 | CK19: =(CI20-CI19) -> 0 | CM19: 14 | CP19: =(CN20-CN19)*60 -> 0 | CQ19: =(CO20-CO19) -> 0 | CS19: 14 | CV19: =(CT20-CT19)*60 -> 0 | CW19: =(CU20-CU19) -> 0 | CY19: 14 | DB19: =(CZ20-CZ19)*60 -> 0 | DC19: =(DA20-DA19) -> 0 | DE19: 14 | DH19: =(DF20-DF19)*60 -> 0 | DI19: =(DG20-DG19) -> 0
B20: 45762 | C20: tue | D20: 0 | E20: 0 | F20: 0 | G20: 0 | H20: 0 | I20: 0 | J20: 0 | K20: 0 | L20: 0 | M20: 0 | N20: 0 | O20: 0 | AH20: 0 | AI20: 0 | AJ20: =AI20-E20 -> 0 | AK20: =AI20-AH20 -> 0 | AL20: 0 | AM20: =AL20-I20 -> 0 | AO20: 1 | AP20: =AO20-K20 -> 1 | AR20: 0 | AS20: =AR20-M20 -> 0 | AZ20: =(BA21-BA20)*240 -> 0 | BA20: 2753.6 | BC20: =(BD21-BD20)*60 -> 0 | BD20: 2457.3 | BE20: =BC20/60 -> 0 | BH20: 15 | BI20: =(BJ21-BJ20) -> 1 | BJ20: 1796376 | BK20: =(BL21-BL20)*60 -> 6 | BL20: 4656.1 | BN20: =(BO21-BO20) -> 0 | BP20: =(BQ21-BQ20)*60 -> 0 | BS20: =(BT21-BT20) -> 0 | BU20: =(BV21-BV20)*60 -> 0 | CA20: 15 | CB20: 71626.45 | CC20: 777165 | CD20: =(CB21-CB20)*60 -> 0 | CE20: =CC21-CC20 -> 0 | CG20: 15 | CJ20: =(CH21-CH20)*60 -> 0 | CK20: =(CI21-CI20) -> 0 | CM20: 15 | CP20: =(CN21-CN20)*60 -> 0 | CQ20: =(CO21-CO20) -> 0 | CS20: 15 | CV20: =(CT21-CT20)*60 -> 0 | CW20: =(CU21-CU20) -> 0 | CY20: 15 | DB20: =(CZ21-CZ20)*60 -> 0 | DC20: =(DA21-DA20) -> 0 | DE20: 15 | DH20: =(DF21-DF20)*60 -> 0 | DI20: =(DG21-DG20) -> 0
B21: 45763 | C21: wed | D21: 220 | E21: 2903 | F21: 0 | G21: 0 | H21: 220 | I21: 1794 | J21: 220 | K21: 3174 | L21: 220 | M21: 2445.31 | N21: 220 | O21: 1327.41 | AH21: 1776.63 | AI21: 1777 | AJ21: =AI21-E21 -> -1126 | AK21: =AI21-AH21 -> 0.37 | AL21: 0 | AM21: =AL21-I21 -> -1794 | AO21: 1163 | AP21: =AO21-K21 -> -2011 | AR21: 0 | AS21: =AR21-M21 -> -2445.31 | AZ21: =(BA22-BA21)*240 -> 576 | BA21: 2753.6 | BC21: =(BD22-BD21)*60 -> 102 | BD21: 2457.3 | BE21: =BC21/60 -> 1.7 | BH21: 16 | BI21: =(BJ22-BJ21) -> 1163 | BJ21: 1796377 | BK21: =(BL22-BL21)*60 -> 126 | BL21: 4656.2 | BN21: =(BO22-BO21) -> 0 | BP21: =(BQ22-BQ21)*60 -> 0 | BS21: =(BT22-BT21) -> 0 | BU21: =(BV22-BV21)*60 -> 0 | CA21: 16 | CB21: 71626.45 | CC21: 777165 | CD21: =(CB22-CB21)*60 -> 0 | CE21: =CC22-CC21 -> 0 | CG21: 16 | CJ21: =(CH22-CH21)*60 -> 0 | CK21: =(CI22-CI21) -> 0 | CM21: 16 | CP21: =(CN22-CN21)*60 -> 0 | CQ21: =(CO22-CO21) -> 0 | CS21: 16 | CV21: =(CT22-CT21)*60 -> 0 | CW21: =(CU22-CU21) -> 0 | CY21: 16 | DB21: =(CZ22-CZ21)*60 -> 0 | DC21: =(DA22-DA21) -> 0 | DE21: 16 | DH21: =(DF22-DF21)*60 -> 0 | DI21: =(DG22-DG21) -> 0
B22: 45764 | C22: thu | D22: 0 | E22: 0 | F22: 0 | G22: 0 | H22: 0 | I22: 0 | J22: 0 | K22: 0 | L22: 0 | M22: 0 | N22: 0 | O22: 0 | AH22: 0 | AI22: 0 | AJ22: =AI22-E22 -> 0 | AK22: =AI22-AH22 -> 0 | AL22: 831 | AM22: =AL22-I22 -> 831 | AO22: 3 | AP22: =AO22-K22 -> 3 | AR22: 1210 | AS22: =AR22-M22 -> 1210 | AZ22: =(BA23-BA22)*240 -> 0 | BA22: 2756 | BC22: =(BD23-BD22)*60 -> 0 | BD22: 2459 | BE22: =BC22/60 -> 0 | BH22: 17 | BI22: =(BJ23-BJ22) -> 3 | BJ22: 1797540 | BK22: =(BL23-BL22)*60 -> 6 | BL22: 4658.3 | BN22: =(BO23-BO22) -> 0 | BP22: =(BQ23-BQ22)*60 -> 0 | BS22: =(BT23-BT22) -> 0 | BU22: =(BV23-BV22)*60 -> 0 | CA22: 17 | CB22: 71626.45 | CC22: 777165 | CD22: =(CB23-CB22)*60 -> 0 | CE22: =CC23-CC22 -> 0 | CG22: 17 | CJ22: =(CH23-CH22)*60 -> 0 | CK22: =(CI23-CI22) -> 0 | CM22: 17 | CP22: =(CN23-CN22)*60 -> 0 | CQ22: =(CO23-CO22) -> 0 | CS22: 17 | CV22: =(CT23-CT22)*60 -> 0 | CW22: =(CU23-CU22) -> 0 | CY22: 17 | DB22: =(CZ23-CZ22)*60 -> 0 | DC22: =(DA23-DA22) -> 0 | DE22: 17 | DH22: =(DF23-DF22)*60 -> 0 | DI22: =(DG23-DG22) -> 0
